Workbook

Sheet Lisez-moi
A1: Chiffrage de l'espace Santé
A2: La grande transmission : https://bonquentin-collab.github.io/Create-Website/
A4: Contenu
A5: Leviers : CSG des pensions au taux normal alignée sur les salaires, cotisation maladie sur les pensions de base, bouclier santé ; recettes, coût, effet sur le déficit de la branche maladie, perdants et gagnants.
A6: Usagers : leviers sur les plus gros consommateurs de soins et les complémentaires (franchises et participations, ticket modérateur, ALD, dépassements d'honoraires, TSA, forfait social des contrats d'entreprise) ; qui paie (patients, primes, employeurs, médecins) et combien par âge.
A7: Effort : taux d'effort pour la santé par niveau de vie, actifs et retraités (Drees, ER 1345, tableau C), et ce qu'ajoutent la CSG et la cotisation choisies.
A8: Bouclier : groupes de ménages classés par taux d'effort en primes et restes à charge (Drees, encadré 3), découpage des tops, profil linéaire et coût du plafond choisi.
A9: Sources : références de chaque donnée.
A10: Vérification
A11: Avec les réglages par défaut du site, les résultats sont ceux du site. Le coût du bouclier est calculé ici en forme exacte (intégrale d'un profil linéaire) ; le site l'approche par 200 points par groupe : écart négligeable (voir la feuille Bouclier).
A12: Limites
A13: Coût du bouclier : revenus supposés égaux entre groupes, ce qui le majore probablement ; aucun effet de comportement. Part de chaque niveau de vie soumise à chaque taux de CSG : estimation du site d'après les seuils de CSG.
... A23: Fond vert pâle : résultat principal

Sheet Leviers
A1: Faire contribuer davantage les retraités qui le peuvent, protéger ceux pour qui la santé coûte le plus
A4: Aligner la CSG des pensions au taux normal sur celle des salaires | B4: Oui
A5: Cotisation maladie sur les pensions de base (retraités au taux médian ou normal) | B5: 0.01
A6: Créer un bouclier santé | B6: Oui
A7: Plafond d'effort en primes et restes à charge (% du revenu) | B7: 10
A8: Votre pension brute mensuelle totale (€) | B8: 2500
A9: Votre taux de CSG | B9: normal
A10: Paramètres
A11: Paramètre | B11: Valeur | C11: Type | D11: Comment c'est calculé | E11: Source
A12: Taux de CSG sur les revenus d'activité | B12: 0.092 | C12: Loi ou barème | D12: Taux légal. | E12: Code de la sécurité sociale, art. L136-8
A13: Taux normal de CSG sur les pensions | B13: 0.083 | C13: Loi ou barème | D13: Barème légal ; seuils confirmés par l'IPP (note n° 129, encadré 1). | E13: Code de la sécurité sociale, art. L136-8 ; seuils 2025 : service-public.gouv.fr
A14: Assiette des pensions au taux normal (Md€) | B14: 190.5 | C14: Calcul du site | D14: Calées sur l'IPP (voir le classeur Retraites). | E14: Estimation du site, calibrée sur les recettes de CSG 2025 (CCSS, mai 2026)
A15: Assiette des pensions au taux médian (Md€) | B15: 118.7 | C15: Calcul du site | D15: Calées sur l'IPP (voir le classeur Retraites). | E15: Idem
A16: Part de la pension venant des régimes de base | B16: 0.67 | C16: Calcul du site | D16: 6,6 Md€ économisés par un gel de 2,5 % ÷ 0,025 = 264 Md€ de pensions de base, sur ≈ 400 Md€. | E16: IPP, Perspectives budgétaires 2027, chapitre 3 : sous-indexation des retraites (Aubert, Tô, Tochev, 2026)
A17: Part des pensions dans le revenu des retraités | B17: 0.778 | C17: Calcul du site | D17: Voir le classeur Retraites. | E17: COR, rapport annuel juin 2026, figure 3.8 : pensions 77,8 % du revenu des ménages retraités, revenus d'activité 84,1 % de celui des ménages actifs
A18: Retraités de droit direct | B18: 17300000 | C18: Chiffre publié | D18: Repris tel quel (dont 16,4 en France). | E18: Drees, effectifs de retraités fin 2024 (17,3 millions de retraités de droit direct, dont 16,4 en France)
A19: Part des retraités au taux normal | B19: 0.29 | C19: Chiffre publié | D19: Retraités du régime général au 31 décembre 2024. | E19: CNAV, recueil statistique 2025, retraités du régime général fin 2024
A20: Part des retraités au taux médian | B20: 0.27 | C20: Chiffre publié | D20: Retraités du régime général au 31 décembre 2024. | E20: CNAV, recueil statistique 2025, retraités du régime général fin 2024
A21: Solde de la branche maladie du régime général, 2026 (Md€) | B21: -13.8 | C21: Chiffre publié | D21: Repris tel quel. | E21: Commission des comptes de la sécurité sociale, rapport de mai 2026
A22: Cotisation maladie existante sur les complémentaires | B22: 0.01 | C22: Loi ou barème | D22: Retraités au taux médian ou normal de CSG. | E22: Question écrite n° 161 à l'Assemblée nationale, 8 octobre 2024 ; service-public.gouv.fr (prélèvements sur les pensions)
A24: Résultats
A25: Recettes de la CSG alignée (Md€) | B25: =IF(Leviers!$B$4="Oui",Leviers!$B$14*(Leviers!$B$12-Leviers!$B$13),0) -> 1.7145
A26: Recettes de la cotisation maladie (Md€) | B26: =Leviers!$B$5*(Leviers!$B$15+Leviers!$B$14)*Leviers!$B$16 -> 2.07164
A27: Ce que les retraités versent en plus (Md€) | B27: =B25+B26 -> 3.78614
A28: Autres leviers : gros consommateurs et complémentaires (Md€, feuille Usagers) | B28: =Usagers!$B$54 -> 0
A29: Coût du bouclier (Md€), recalculé sur les efforts relevés par les autres leviers | B29: =IF(Leviers!$B$6="Oui",Bouclier!$C$44,0) -> 3.3650305
A30: Effet net pour l'Assurance maladie (Md€) | B30: =B27+B28-B29 -> 0.42110947
A31: Part du déficit 2026 comblée | B31: =IF(B30>0,B30/ABS(Leviers!$B$21),0) -> 0.030515179
A32: Ménages protégés par le bouclier | B32: =IF(Leviers!$B$6="Oui",Bouclier!$C$45,0) -> 1942105.3
A33: Part de l'aide pour des ménages de retraités | B33: =IF(Leviers!$B$6="Oui",Bouclier!$C$46,0) -> 0.76972872
A34: … dont retraités modestes | B34: =IF(Leviers!$B$6="Oui",Bouclier!$C$47,0) -> 0.57672167
A35: Retraités qui paient plus | B35: =MAX(IF(Leviers!$B$4="Oui",Leviers!$B$19,0),IF(Leviers!$B$5>0,Leviers!$B$19+Leviers!$B$20,0))*Leviers!$B$18 -> 9688000
A36: Solde pour les retraités : versé en plus (CSG, cotisation, autres leviers), net de ce que le bouclier leur rend (Md€) | B36: =B27+Usagers!$B$57-B29*B33 -> 1.1959794
A37: Votre perte (€ brut par mois) | B37: =Leviers!$B$8*(IF(AND(Leviers!$B$4="Oui",Leviers!$B$9="normal"),Leviers!$B$12-Leviers!$B$13,0)+IF(OR(Leviers!$B$9="median",Leviers!$B$9="normal"),Leviers!$B$5*Leviers!$B$16,0)) -> 39.25

Sheet Effort
A1: Taux d'effort pour la santé, avant et après (en % du revenu)
A2: Drees, ER 1345, tableau complémentaire C (Ines-Omar 2019) ; ajout de la réforme : estimation du site.
A4: Niveau de vie | B4: Champ | C4: Sécurité sociale | D4: Primes | E4: Restes à charge | F4: Total avant | G4: Part exposée au taux normal | H4: Part exposée au taux médian ou normal | I4: Ajout CSG et cotisation (points) | J4: Ajout des autres leviers (points)
A5: Très modestes | B5: Actifs en emploi (moins de 60 % du niveau de vie médian) | C5: 11.42 | D5: 2.38 | E5: 1.53 | F5: =SUM(C5:E5) -> 15.33 | I5: =0 -> 0 | J5: =E5*Usagers!$B$59/Usagers!$B$63+D5*Usagers!$B$61/Usagers!$B$65+100*Usagers!$E$54/Usagers!$B$67 -> 0
A6: Très modestes | B6: Retraités (moins de 60 % du niveau de vie médian) | C6: 6.32 | D6: 6 | E6: 1.94 | F6: =SUM(C6:E6) -> 14.26 | G6: 0 | H6: 0 | I6: =100*Leviers!$B$17*(IF(Leviers!$B$4="Oui",Leviers!$B$12-Leviers!$B$13,0)*G6+Leviers!$B$5*Leviers!$B$16*H6) -> 0 | J6: =E6*Usagers!$B$60/Usagers!$B$64+D6*Usagers!$B$62/Usagers!$B$66 -> 0
A7: Plutôt modestes | B7: Actifs en emploi (60 à 90 %) | C7: 12.59 | D7: 2.15 | E7: 0.92 | F7: =SUM(C7:E7) -> 15.66 | I7: =0 -> 0 | J7: =E7*Usagers!$B$59/Usagers!$B$63+D7*Usagers!$B$61/Usagers!$B$65+100*Usagers!$E$54/Usagers!$B$67 -> 0
A8: Plutôt modestes | B8: Retraités (60 à 90 %) | C8: 6.13 | D8: 5.81 | E8: 1.63 | F8: =SUM(C8:E8) -> 13.57 | G8: 0 | H8: 0.6 | I8: =100*Leviers!$B$17*(IF(Leviers!$B$4="Oui",Leviers!$B$12-Leviers!$B$13,0)*G8+Leviers!$B$5*Leviers!$B$16*H8) -> 0.312756 | J8: =E8*Usagers!$B$60/Usagers!$B$64+D8*Usagers!$B$62/Usagers!$B$66 -> 0
A9: Médians | B9: Actifs en emploi (90 à 120 %) | C9: 14.06 | D9: 1.79 | E9: 0.71 | F9: =SUM(C9:E9) -> 16.56 | I9: =0 -> 0 | J9: =E9*Usagers!$B$59/Usagers!$B$63+D9*Usagers!$B$61/Usagers!$B$65+100*Usagers!$E$54/Usagers!$B$67 -> 0
A10: Médians | B10: Retraités (90 à 120 %) | C10: 7.19 | D10: 4.53 | E10: 1.47 | F10: =SUM(C10:E10) -> 13.19 | G10: 0.5 | H10: 1 | I10: =100*Leviers!$B$17*(IF(Leviers!$B$4="Oui",Leviers!$B$12-Leviers!$B$13,0)*G10+Leviers!$B$5*Leviers!$B$16*H10) -> 0.87136 | J10: =E10*Usagers!$B$60/Usagers!$B$64+D10*Usagers!$B$62/Usagers!$B$66 -> 0
A11: Plutôt aisés | B11: Actifs en emploi (120 à 180 %) | C11: 15.41 | D11: 1.56 | E11: 0.57 | F11: =SUM(C11:E11) -> 17.54 | I11: =0 -> 0 | J11: =E11*Usagers!$B$59/Usagers!$B$63+D11*Usagers!$B$61/Usagers!$B$65+100*Usagers!$E$54/Usagers!$B$67 -> 0
A12: Plutôt aisés | B12: Retraités (120 à 180 %) | C12: 8.18 | D12: 3.46 | E12: 1.49 | F12: =SUM(C12:E12) -> 13.13 | G12: 1 | H12: 1 | I12: =100*Leviers!$B$17*(IF(Leviers!$B$4="Oui",Leviers!$B$12-Leviers!$B$13,0)*G12+Leviers!$B$5*Leviers!$B$16*H12) -> 1.22146 | J12: =E12*Usagers!$B$60/Usagers!$B$64+D12*Usagers!$B$62/Usagers!$B$66 -> 0
A13: Très aisés | B13: Actifs en emploi (plus de 180 %) | C13: 16.16 | D13: 1.13 | E13: 0.41 | F13: =SUM(C13:E13) -> 17.7 | I13: =0 -> 0 | J13: =E13*Usagers!$B$59/Usagers!$B$63+D13*Usagers!$B$61/Usagers!$B$65+100*Usagers!$E$54/Usagers!$B$67 -> 0
A14: Très aisés | B14: Retraités (plus de 180 %) | C14: 7.74 | D14: 2.37 | E14: 1.14 | F14: =SUM(C14:E14) -> 11.25 | G14: 1 | H14: 1 | I14: =100*Leviers!$B$17*(IF(Leviers!$B$4="Oui",Leviers!$B$12-Leviers!$B$13,0)*G14+Leviers!$B$5*Leviers!$B$16*H14) -> 1.22146 | J14: =E14*Usagers!$B$60/Usagers!$B$64+D14*Usagers!$B$62/Usagers!$B$66 -> 0
A16: Niveau de vie | C16: Actifs avant | D16: Retraités avant | E16: Retraités après | F16: Écart actifs − retraités avant | G16: Écart après | H16: Actifs après
A17: Très modestes | C17: =F5 -> 15.33 | D17: =F6 -> 14.26 | E17: =F6+I6+J6 -> 14.26 | F17: =C17-D17 -> 1.07 | G17: =H17-E17 -> 1.07 | H17: =F5+J5 -> 15.33
A18: Plutôt modestes | C18: =F7 -> 15.66 | D18: =F8 -> 13.57 | E18: =F8+I8+J8 -> 13.882756 | F18: =C18-D18 -> 2.09 | G18: =H18-E18 -> 1.777244 | H18: =F7+J7 -> 15.66
A19: Médians | C19: =F9 -> 16.56 | D19: =F10 -> 13.19 | E19: =F10+I10+J10 -> 14.06136 | F19: =C19-D19 -> 3.37 | G19: =H19-E19 -> 2.49864 | H19: =F9+J9 -> 16.56
A20: Plutôt aisés | C20: =F11 -> 17.54 | D20: =F12 -> 13.13 | E20: =F12+I12+J12 -> 14.35146 | F20: =C20-D20 -> 4.41 | G20: =H20-E20 -> 3.18854 | H20: =F11+J11 -> 17.54
A21: Très aisés | C21: =F13 -> 17.7 | D21: =F14 -> 11.25 | E21: =F14+I14+J14 -> 12.47146 | F21: =C21-D21 -> 6.45 | G21: =H21-E21 -> 5.22854 | H21: =F13+J13 -> 17.7
A23: Exposition : part de la pension brute des retraités de chaque niveau de vie touchée par chaque levier, estimée d'après les seuils de CSG 2025 (taux normal vers 2 400 € de pension brute pour une personne seule, taux médian vers 1 550 €).

Sheet Bouclier
A1: Bouclier santé : coût et bénéficiaires
A2: Primes de complémentaire et restes à charge en % du revenu disponible après financement de l'AMO, ménages classés selon ce taux (Drees, ER 1345, encadré 3 et tableau G, 2019).
A4: Données publiées
A5: Groupe | B5: Part des ménages | C5: Taux d'effort moyen (%) | D5: Retraités modestes (%) | E5: Retraités médians à aisés (%)
A6: D1 | B6: 0.1 | C6: 0.28 | D6: 9.02 | E6: 4.21
A7: D2 | B7: 0.1 | C7: 1.21 | D7: 5.57 | E7: 4.37
A8: D3 | B8: 0.1 | C8: 1.85 | D8: 3.15 | E8: 7.63
A9: D4 | B9: 0.1 | C9: 2.46 | D9: 2.49 | E9: 12.68
A10: D5 | B10: 0.1 | C10: 3.07 | D10: 3.39 | E10: 20.18
A11: D6 | B11: 0.1 | C11: 3.75 | D11: 5.41 | E11: 27.75
A12: D7 | B12: 0.1 | C12: 4.58 | D12: 9.84 | E12: 36.95
A13: D8 | B13: 0.1 | C13: 5.68 | D13: 21.99 | E13: 42.03
A14: D9 | B14: 0.1 | C14: 7.33 | D14: 36.04 | E14: 38.1
A15: D10 | B15: 0.1 | C15: 12.68 | D15: 53.65 | E15: 26.84
A16: Top 5 % | B16: 0.05 | C16: 15.82 | D16: 56.21 | E16: 23.99
A17: Top 2 % | B17: 0.02 | C17: 21.2 | D17: 59.2 | E17: 18.28
A18: Top 1 % | B18: 0.01 | C18: 26.87 | D18: 58.76 | E18: 14.43
A21: Groupes disjoints et profil linéaire (bords choisis pour conserver la moyenne de chaque groupe ; efforts relevés de la hausse des primes et restes à charge due aux autres leviers, feuille Usagers)
A22: Groupe | B22: Part | C22: Effort moyen | D22: Retraités modestes | E22: Retraités médians à aisés | F22: Bord gauche | G22: Bord droit | H22: Bas | I22: Haut | J22: Effort au-delà du plafond | K22: Ménages bénéficiaires (part)
A23: D1 | B23: =B6 -> 0.1 | C23: =C6*(1+Usagers!$B$68) -> 0.28 | D23: =D6/100 -> 0.0902 | E23: =E6/100 -> 0.0421 | F23: =0 -> 0 | G23: =MAX(0,2*C23-F23) -> 0.56 | H23: =MIN(F23,G23) -> 0 | I23: =MAX(F23,G23) -> 0.56 | J23: =IF(I23<=Leviers!$B$7,0,IF(H23>=Leviers!$B$7,B23*((F23+G23)/2-Leviers!$B$7),B23*(I23-Leviers!$B$7)/(I23-H23)*(I23-Leviers!$B$7)/2)) -> 0 | K23: =IF(I23<=Leviers!$B$7,0,IF(H23>=Leviers!$B$7,B23,B23*(I23-Leviers!$B$7)/(I23-H23))) -> 0
A24: D2 | B24: =B7 -> 0.1 | C24: =C7*(1+Usagers!$B$68) -> 1.21 | D24: =D7/100 -> 0.0557 | E24: =E7/100 -> 0.0437 | F24: =G23 -> 0.56 | G24: =MAX(0,2*C24-F24) -> 1.86 | H24: =MIN(F24,G24) -> 0.56 | I24: =MAX(F24,G24) -> 1.86 | J24: =IF(I24<=Leviers!$B$7,0,IF(H24>=Leviers!$B$7,B24*((F24+G24)/2-Leviers!$B$7),B24*(I24-Leviers!$B$7)/(I24-H24)*(I24-Leviers!$B$7)/2)) -> 0 | K24: =IF(I24<=Leviers!$B$7,0,IF(H24>=Leviers!$B$7,B24,B24*(I24-Leviers!$B$7)/(I24-H24))) -> 0
A25: D3 | B25: =B8 -> 0.1 | C25: =C8*(1+Usagers!$B$68) -> 1.85 | D25: =D8/100 -> 0.0315 | E25: =E8/100 -> 0.0763 | F25: =G24 -> 1.86 | G25: =MAX(0,2*C25-F25) -> 1.84 | H25: =MIN(F25,G25) -> 1.84 | I25: =MAX(F25,G25) -> 1.86 | J25: =IF(I25<=Leviers!$B$7,0,IF(H25>=Leviers!$B$7,B25*((F25+G25)/2-Leviers!$B$7),B25*(I25-Leviers!$B$7)/(I25-H25)*(I25-Leviers!$B$7)/2)) -> 0 | K25: =IF(I25<=Leviers!$B$7,0,IF(H25>=Leviers!$B$7,B25,B25*(I25-Leviers!$B$7)/(I25-H25))) -> 0
A26: D4 | B26: =B9 -> 0.1 | C26: =C9*(1+Usagers!$B$68) -> 2.46 | D26: =D9/100 -> 0.0249 | E26: =E9/100 -> 0.1268 | F26: =G25 -> 1.84 | G26: =MAX(0,2*C26-F26) -> 3.08 | H26: =MIN(F26,G26) -> 1.84 | I26: =MAX(F26,G26) -> 3.08 | J26: =IF(I26<=Leviers!$B$7,0,IF(H26>=Leviers!$B$7,B26*((F26+G26)/2-Leviers!$B$7),B26*(I26-Leviers!$B$7)/(I26-H26)*(I26-Leviers!$B$7)/2)) -> 0 | K26: =IF(I26<=Leviers!$B$7,0,IF(H26>=Leviers!$B$7,B26,B26*(I26-Leviers!$B$7)/(I26-H26))) -> 0
A27: D5 | B27: =B10 -> 0.1 | C27: =C10*(1+Usagers!$B$68) -> 3.07 | D27: =D10/100 -> 0.0339 | E27: =E10/100 -> 0.2018 | F27: =G26 -> 3.08 | G27: =MAX(0,2*C27-F27) -> 3.06 | H27: =MIN(F27,G27) -> 3.06 | I27: =MAX(F27,G27) -> 3.08 | J27: =IF(I27<=Leviers!$B$7,0,IF(H27>=Leviers!$B$7,B27*((F27+G27)/2-Leviers!$B$7),B27*(I27-Leviers!$B$7)/(I27-H27)*(I27-Leviers!$B$7)/2)) -> 0 | K27: =IF(I27<=Leviers!$B$7,0,IF(H27>=Leviers!$B$7,B27,B27*(I27-Leviers!$B$7)/(I27-H27))) -> 0
A28: D6 | B28: =B11 -> 0.1 | C28: =C11*(1+Usagers!$B$68) -> 3.75 | D28: =D11/100 -> 0.0541 | E28: =E11/100 -> 0.2775 | F28: =G27 -> 3.06 | G28: =MAX(0,2*C28-F28) -> 4.44 | H28: =MIN(F28,G28) -> 3.06 | I28: =MAX(F28,G28) -> 4.44 | J28: =IF(I28<=Leviers!$B$7,0,IF(H28>=Leviers!$B$7,B28*((F28+G28)/2-Leviers!$B$7),B28*(I28-Leviers!$B$7)/(I28-H28)*(I28-Leviers!$B$7)/2)) -> 0 | K28: =IF(I28<=Leviers!$B$7,0,IF(H28>=Leviers!$B$7,B28,B28*(I28-Leviers!$B$7)/(I28-H28))) -> 0
A29: D7 | B29: =B12 -> 0.1 | C29: =C12*(1+Usagers!$B$68) -> 4.58 | D29: =D12/100 -> 0.0984 | E29: =E12/100 -> 0.3695 | F29: =G28 -> 4.44 | G29: =MAX(0,2*C29-F29) -> 4.72 | H29: =MIN(F29,G29) -> 4.44 | I29: =MAX(F29,G29) -> 4.72 | J29: =IF(I29<=Leviers!$B$7,0,IF(H29>=Leviers!$B$7,B29*((F29+G29)/2-Leviers!$B$7),B29*(I29-Leviers!$B$7)/(I29-H29)*(I29-Leviers!$B$7)/2)) -> 0 | K29: =IF(I29<=Leviers!$B$7,0,IF(H29>=Leviers!$B$7,B29,B29*(I29-Leviers!$B$7)/(I29-H29))) -> 0
A30: D8 | B30: =B13 -> 0.1 | C30: =C13*(1+Usagers!$B$68) -> 5.68 | D30: =D13/100 -> 0.2199 | E30: =E13/100 -> 0.4203 | F30: =G29 -> 4.72 | G30: =MAX(0,2*C30-F30) -> 6.64 | H30: =MIN(F30,G30) -> 4.72 | I30: =MAX(F30,G30) -> 6.64 | J30: =IF(I30<=Leviers!$B$7,0,IF(H30>=Leviers!$B$7,B30*((F30+G30)/2-Leviers!$B$7),B30*(I30-Leviers!$B$7)/(I30-H30)*(I30-Leviers!$B$7)/2)) -> 0 | K30: =IF(I30<=Leviers!$B$7,0,IF(H30>=Leviers!$B$7,B30,B30*(I30-Leviers!$B$7)/(I30-H30))) -> 0
A31: D9 | B31: =B14 -> 0.1 | C31: =C14*(1+Usagers!$B$68) -> 7.33 | D31: =D14/100 -> 0.3604 | E31: =E14/100 -> 0.381 | F31: =G30 -> 6.64 | G31: =MAX(0,2*C31-F31) -> 8.02 | H31: =MIN(F31,G31) -> 6.64 | I31: =MAX(F31,G31) -> 8.02 | J31: =IF(I31<=Leviers!$B$7,0,IF(H31>=Leviers!$B$7,B31*((F31+G31)/2-Leviers!$B$7),B31*(I31-Leviers!$B$7)/(I31-H31)*(I31-Leviers!$B$7)/2)) -> 0 | K31: =IF(I31<=Leviers!$B$7,0,IF(H31>=Leviers!$B$7,B31,B31*(I31-Leviers!$B$7)/(I31-H31))) -> 0
A32: 90 à 95 % | B32: =B15-B16 -> 0.05 | C32: =(C15*B15-C16*B16)/(B15-B16)*(1+Usagers!$B$68) -> 9.54 | D32: =(D15*B15-D16*B16)/(B15-B16)/100 -> 0.5109 | E32: =(E15*B15-E16*B16)/(B15-B16)/100 -> 0.2969 | F32: =G31 -> 8.02 | G32: =MAX(0,2*C32-F32) -> 11.06 | H32: =MIN(F32,G32) -> 8.02 | I32: =MAX(F32,G32) -> 11.06 | J32: =IF(I32<=Leviers!$B$7,0,IF(H32>=Leviers!$B$7,B32*((F32+G32)/2-Leviers!$B$7),B32*(I32-Leviers!$B$7)/(I32-H32)*(I32-Leviers!$B$7)/2)) -> 0.0092401316 | K32: =IF(I32<=Leviers!$B$7,0,IF(H32>=Leviers!$B$7,B32,B32*(I32-Leviers!$B$7)/(I32-H32))) -> 0.017434211
A33: 95 à 98 % | B33: =B16-B17 -> 0.03 | C33: =(C16*B16-C17*B17)/(B16-B17)*(1+Usagers!$B$68) -> 12.233333 | D33: =(D16*B16-D17*B17)/(B16-B17)/100 -> 0.54216667 | E33: =(E16*B16-E17*B17)/(B16-B17)/100 -> 0.27796667 | F33: =G32 -> 11.06 | G33: =MAX(0,2*C33-F33) -> 13.406667 | H33: =MIN(F33,G33) -> 11.06 | I33: =MAX(F33,G33) -> 13.406667 | J33: =IF(I33<=Leviers!$B$7,0,IF(H33>=Leviers!$B$7,B33*((F33+G33)/2-Leviers!$B$7),B33*(I33-Leviers!$B$7)/(I33-H33)*(I33-Leviers!$B$7)/2)) -> 0.067 | K33: =IF(I33<=Leviers!$B$7,0,IF(H33>=Leviers!$B$7,B33,B33*(I33-Leviers!$B$7)/(I33-H33))) -> 0.03
A34: 98 à 99 % | B34: =B17-B18 -> 0.01 | C34: =(C17*B17-C18*B18)/(B17-B18)*(1+Usagers!$B$68) -> 15.53 | D34: =(D17*B17-D18*B18)/(B17-B18)/100 -> 0.5964 | E34: =(E17*B17-E18*B18)/(B17-B18)/100 -> 0.2213 | F34: =G33 -> 13.406667 | G34: =MAX(0,2*C34-F34) -> 17.653333 | H34: =MIN(F34,G34) -> 13.406667 | I34: =MAX(F34,G34) -> 17.653333 | J34: =IF(I34<=Leviers!$B$7,0,IF(H34>=Leviers!$B$7,B34*((F34+G34)/2-Leviers!$B$7),B34*(I34-Leviers!$B$7)/(I34-H34)*(I34-Leviers!$B$7)/2)) -> 0.0553 | K34: =IF(I34<=Leviers!$B$7,0,IF(H34>=Leviers!$B$7,B34,B34*(I34-Leviers!$B$7)/(I34-H34))) -> 0.01
A35: 1 % le plus exposé | B35: =B18 -> 0.01 | C35: =C18*(1+Usagers!$B$68) -> 26.87 | D35: =D18/100 -> 0.5876 | E35: =E18/100 -> 0.1443 | F35: =G34 -> 17.653333 | G35: =MAX(0,2*C35-F35) -> 36.086667 | H35: =MIN(F35,G35) -> 17.653333 | I35: =MAX(F35,G35) -> 36.086667 | J35: =IF(I35<=Leviers!$B$7,0,IF(H35>=Leviers!$B$7,B35*((F35+G35)/2-Leviers!$B$7),B35*(I35-Leviers!$B$7)/(I35-H35)*(I35-Leviers!$B$7)/2)) -> 0.1687 | K35: =IF(I35<=Leviers!$B$7,0,IF(H35>=Leviers!$B$7,B35,B35*(I35-Leviers!$B$7)/(I35-H35))) -> 0.01
A36: Total | B36: =SUM(B23:B35) -> 1 | C36: =SUMPRODUCT(B23:B35,C23:C35) -> 4.289 | J36: =SUM(J23:J35) -> 0.30024013 | K36: =SUM(K23:K35) -> 0.067434211
A38: Paramètres et résultats
A39: Taux d'effort moyen publié, ensemble (%) | C39: 4.29 | D39: Drees, encadré 3 | I39: Moyenne publiée des taux d'effort des dix dixièmes.
A40: Primes et restes à charge moyens par ménage, 2019 (€) | C40: 1408 | D40: Drees, tableau A : 1 021 € + 387 € | I40: 1 021 € de primes + 387 € de restes à charge.
A41: Ménages (champ de l'enquête) | C41: 28800000 | D41: Insee Première n° 1875, 2021 (champ de 63,4 millions de personnes) ; 2,2 personnes par ménage | I41: 63,4 millions de personnes ÷ 2,2 personnes par ménage.
A42: Évolution 2019 → 2024 des dépenses payées par les complémentaires et les ménages | C42: 1.1857207 | D42: Drees, comptes de la santé : 44,3 Md€ en 2019, 52,5 Md€ en 2024 | I42: (32,52 + 19,96) ÷ (26,74 + 17,52) Md€.
A43: Primes et restes à charge, 2024 (Md€) | C43: =C40*C41*C42/1000000000 -> 48.08145
A44: Bouclier : coût (Md€) | C44: =J36/C39*C43 -> 3.3650305
...

Sheet Usagers
A1: Les plus gros consommateurs de soins et les complémentaires santé
A2: Franchises, ticket modérateur, ALD, dépassements d'honoraires, TSA, forfait social des contrats d'entreprise : ce que gagne l'Assurance maladie et qui paie.
A3: Vos réglages
A4: Plafond annuel des franchises et participations (€, total) | B4: 140
A5: Multiplicateur des montants unitaires (1 = actuels) | B5: 1
A6: Ticket modérateur des consultations | B6: 0.3
A7: ALD : cures thermales remboursées comme pour tous | B7: Non
A8: ALD : suppression des ALD « non exonérantes » | B8: Non
A9: Plafonnement des dépassements : baisse | B9: 0
A10: Taxe sur les dépassements restants | B10: 0
A11: Variation de la TSA (points) | B11: 0
A12: Forfait social des contrats d'entreprise | B12: 0.08
A14: Paramètres
A15: Paramètre | B15: Valeur | C15: Type | D15: Comment c'est calculé
A16: Dispersion du modèle de franchises | B16: 1.4 | C16: Hypothèse du site | D16: Choisie pour retrouver les deux points de contrôle officiels.
A17: Multiplicateur des montants 2023 → 2024 (doublement de 2024) | B17: 2 | C17: Chiffre publié | D17: Repris tel quel ; sert à caler le modèle par âge.
A18: Plafond total en 2023 (€) | B18: 100 | C18: Chiffre publié | D18: Repris tel quel ; sert à caler le modèle par âge.
A19: Plafond total actuel (€) | B19: 140 | C19: Loi ou barème | D19: Plafonds relevés de 50 € à 70 € chacun ; montants unitaires inchangés.
A20: Ticket modérateur actuel des consultations | B20: 0.3 | C20: Calcul du site | D20: 1,1 Md€ transférés aux complémentaires pour 30 → 40 % (PLFSS 2025) ÷ 10.
A21: Rendement d'un point de ticket modérateur (Md€) | B21: 0.11 | C21: Calcul du site | D21: 1,1 Md€ transférés aux complémentaires pour 30 → 40 % (PLFSS 2025) ÷ 10.
A22: ALD : cures thermales (Md€) | B22: 0.2 | C22: Chiffre publié | D22: Mesures du PLFSS 2026 abandonnées en LFSS.
A23: ALD : ALD non exonérantes (Md€) | B23: 0.1 | C23: Chiffre publié | D23: Mesures du PLFSS 2026 abandonnées en LFSS.
A24: Dépassements d'honoraires 2024 (Md€) | B24: 4.5 | C24: Chiffre publié | D24: Repris tel quel (milieu retenu : 38,5 %).
A25: Part des dépassements remboursée par les complémentaires | B25: 0.385 | C25: Chiffre publié | D25: Repris tel quel (milieu retenu : 38,5 %).
A26: Part de la population sans complémentaire | B26: 0.05 | C26: Chiffre publié | D26: Repris tel quel.
A27: Taux de TSA | B27: 0.1327 | C27: Loi ou barème | D27: Valeur d'un point : 6,558 ÷ 13,27 ≈ 0,49 Md€ (un peu forte : certains contrats sont taxés à 20,27 %).
... A33: Prime mensuelle à 85 ans (€) | B33: 142 | C33: Chiffre publié | D33: Interpolée linéairement entre ces âges pour répartir une hausse de primes.
A35: Âge | B35: Personnes | C35: Franchises observées 2023 (€) | D35: Âge milieu | E35: Paramètre mu (calé) | F35: Contrôle : modèle 2023 (€) | G35: Franchises avant (€) | H35: Franchises après (€) | I35: Δ franchises (€/pers.) | J35: Ticket modérateur (€) | K35: Remboursement AMO (€) | L35: Dépassements (€) | M35: Prime mensuelle (€) | N35: Actif (21-60 ans) | O35: Ticket mod. (€/pers.) | P35: ALD (€/pers.) | Q35: Dépassements (€/pers.) | R35: Primes : TSA (€/pers.) | S35: Contrats d'entreprise (€/pers.) | T35: Patients (€/pers.) | U35: Via les primes (€/pers.)
A36: 0-10 ans | B36: 8216128 | C36: 0 | D36: 5 | E36: exonérés | F36: =0 -> 0 | G36: =0 -> 0 | H36: =0 -> 0 | I36: =0 -> 0 | J36: 149 | K36: 925 | L36: 88 | M36: =$B$32+($B$33-$B$32)*(MIN(85,MAX(20,D36))-20)/65 -> 36 | N36: 0 | O36: =IF(SUMPRODUCT($B$36:$B$44,$J$36:$J$44)>0,B47*1000000000*J36/SUMPRODUCT($B$36:$B$44,$J$36:$J$44),0) -> 0 | P36: =IF(SUMPRODUCT($B$36:$B$44,$K$36:$K$44)>0,B48*1000000000*K36/SUMPRODUCT($B$36:$B$44,$K$36:$K$44),0) -> 0 | Q36: =-$B$9*$B$24*1000000000*L36/SUMPRODUCT($B$36:$B$44,$L$36:$L$44) -> 0 | R36: =(B50+B52)*1000000000*M36/SUMPRODUCT($B$36:$B$44,$M$36:$M$44) -> 0 | S36: =B51*1000000000*N36/SUMPRODUCT($B$36:$B$44,$N$36:$N$44) -> 0 | T36: =I36+(O36+P36)*$B$26+Q36*(1-$B$25) -> 0 | U36: =(O36+P36)*(1-$B$26)+Q36*$B$25+R36 -> 0
A37: 11-20 ans | B37: 8186259 | C37: 2 | D37: 15.5 | E37: -0.280523 | F37: =EXP((E37+LN($B$17*0.5))+$B$16^2/2)*_xlfn.NORM.S.DIST(((LN($B$18)-(E37+LN($B$17*0.5)))/$B$16)-$B$16,TRUE())+$B$18*(1-_xlfn.NORM.S.DIST(((LN($B$18)-(E37+LN($B$17*0.5)))/$B$16),TRUE())) -> 2.0000005 | G37: =EXP((E37+LN($B$17*1))+$B$16^2/2)*_xlfn.NORM.S.DIST(((LN($B$19)-(E37+LN($B$17*1)))/$B$16)-$B$16,TRUE())+$B$19*(1-_xlfn.NORM.S.DIST(((LN($B$19)-(E37+LN($B$17*1)))/$B$16),TRUE())) -> 3.9766935 | H37: =EXP((E37+LN($B$17*$B$5))+$B$16^2/2)*_xlfn.NORM.S.DIST(((LN($B$4)-(E37+LN($B$17*$B$5)))/$B$16)-$B$16,TRUE())+$B$4*(1-_xlfn.NORM.S.DIST(((LN($B$4)-(E37+LN($B$17*$B$5)))/$B$16),TRUE())) -> 3.9766935 | I37: =H37-G37 -> 0 | J37: 143 | K37: 887 | L37: 263 | M37: =$B$32+($B$33-$B$32)*(MIN(85,MAX(20,D37))-20)/65 -> 36 | N37: 0 | O37: =IF(SUMPRODUCT($B$36:$B$44,$J$36:$J$44)>0,B47*1000000000*J37/SUMPRODUCT($B$36:$B$44,$J$36:$J$44),0) -> 0 | P37: =IF(SUMPRODUCT($B$36:$B$44,$K$36:$K$44)>0,B48*1000000000*K37/SUMPRODUCT($B$36:$B$44,$K$36:$K$44),0) -> 0 | Q37: =-$B$9*$B$24*1000000000*L37/SUMPRODUCT($B$36:$B$44,$L$36:$L$44) -> 0 | R37: =(B50+B52)*1000000000*M37/SUMPRODUCT($B$36:$B$44,$M$36:$M$44) -> 0 | S37: =B51*1000000000*N37/SUMPRODUCT($B$36:$B$44,$N$36:$N$44) -> 0 | T37: =I37+(O37+P37)*$B$26+Q37*(1-$B$25) -> 0 | U37: =(O37+P37)*(1-$B$26)+Q37*$B$25+R37 -> 0
A38: 21-30 ans | B38: 7938340 | C38: 14 | D38: 25.5 | E38: 1.802278 | F38: =EXP((E38+LN($B$17*0.5))+$B$16^2/2)*_xlfn.NORM.S.DIST(((LN($B$18)-(E38+LN($B$17*0.5)))/$B$16)-$B$16,TRUE())+$B$18*(1-_xlfn.NORM.S.DIST(((LN($B$18)-(E38+LN($B$17*0.5)))/$B$16),TRUE())) -> 14.000005 | G38: =EXP((E38+LN($B$17*1))+$B$16^2/2)*_xlfn.NORM.S.DIST(((LN($B$19)-(E38+LN($B$17*1)))/$B$16)-$B$16,TRUE())+$B$19*(1-_xlfn.NORM.S.DIST(((LN($B$19)-(E38+LN($B$17*1)))/$B$16),TRUE())) -> 26.185214 | H38: =EXP((E38+LN($B$17*$B$5))+$B$16^2/2)*_xlfn.NORM.S.DIST(((LN($B$4)-(E38+LN($B$17*$B$5)))/$B$16)-$B$16,TRUE())+$B$4*(1-_xlfn.NORM.S.DIST(((LN($B$4)-(E38+LN($B$17*$B$5)))/$B$16),TRUE())) -> 26.185214 | I38: =H38-G38 -> 0 | J38: 169 | K38: 1134 | L38: 145 | M38: =$B$32+($B$33-$B$32)*(MIN(85,MAX(20,D38))-20)/65 -> 44.969231 | N38: 1 | O38: =IF(SUMPRODUCT($B$36:$B$44,$J$36:$J$44)>0,B47*1000000000*J38/SUMPRODUCT($B$36:$B$44,$J$36:$J$44),0) -> 0 | P38: =IF(SUMPRODUCT($B$36:$B$44,$K$36:$K$44)>0,B48*1000000000*K38/SUMPRODUCT($B$36:$B$44,$K$36:$K$44),0) -> 0 | Q38: =-$B$9*$B$24*1000000000*L38/SUMPRODUCT($B$36:$B$44,$L$36:$L$44) -> 0 | R38: =(B50+B52)*1000000000*M38/SUMPRODUCT($B$36:$B$44,$M$36:$M$44) -> 0 | S38: =B51*1000000000*N38/SUMPRODUCT($B$36:$B$44,$N$36:$N$44) -> 0 | T38: =I38+(O38+P38)*$B$26+Q38*(1-$B$25) -> 0 | U38: =(O38+P38)*(1-$B$26)+Q38*$B$25+R38 -> 0
A39: 31-40 ans | B39: 8390307 | C39: 17 | D39: 35.5 | E39: 2.038689 | F39: =EXP((E39+LN($B$17*0.5))+$B$16^2/2)*_xlfn.NORM.S.DIST(((LN($B$18)-(E39+LN($B$17*0.5)))/$B$16)-$B$16,TRUE())+$B$18*(1-_xlfn.NORM.S.DIST(((LN($B$18)-(E39+LN($B$17*0.5)))/$B$16),TRUE())) -> 16.999994 | G39: =EXP((E39+LN($B$17*1))+$B$16^2/2)*_xlfn.NORM.S.DIST(((LN($B$19)-(E39+LN($B$17*1)))/$B$16)-$B$16,TRUE())+$B$19*(1-_xlfn.NORM.S.DIST(((LN($B$19)-(E39+LN($B$17*1)))/$B$16),TRUE())) -> 31.375192 | H39: =EXP((E39+LN($B$17*$B$5))+$B$16^2/2)*_xlfn.NORM.S.DIST(((LN($B$4)-(E39+LN($B$17*$B$5)))/$B$16)-$B$16,TRUE())+$B$4*(1-_xlfn.NORM.S.DIST(((LN($B$4)-(E39+LN($B$17*$B$5)))/$B$16),TRUE())) -> 31.375192 | I39: =H39-G39 -> 0 | J39: 202 | K39: 1477 | L39: 194 | M39: =$B$32+($B$33-$B$32)*(MIN(85,MAX(20,D39))-20)/65 -> 61.276923 | N39: 1 | O39: =IF(SUMPRODUCT($B$36:$B$44,$J$36:$J$44)>0,B47*1000000000*J39/SUMPRODUCT($B$36:$B$44,$J$36:$J$44),0) -> 0 | P39: =IF(SUMPRODUCT($B$36:$B$44,$K$36:$K$44)>0,B48*1000000000*K39/SUMPRODUCT($B$36:$B$44,$K$36:$K$44),0) -> 0 | Q39: =-$B$9*$B$24*1000000000*L39/SUMPRODUCT($B$36:$B$44,$L$36:$L$44) -> 0 | R39: =(B50+B52)*1000000000*M39/SUMPRODUCT($B$36:$B$44,$M$36:$M$44) -> 0 | S39: =B51*1000000000*N39/SUMPRODUCT($B$36:$B$44,$N$36:$N$44) -> 0 | T39: =I39+(O39+P39)*$B$26+Q39*(1-$B$25) -> 0 | U39: =(O39+P39)*(1-$B$26)+Q39*$B$25+R39 -> 0
A40: 41-50 ans | B40: 8488253 | C40: 21 | D40: 45.5 | E40: 2.308914 | F40: =EXP((E40+LN($B$17*0.5))+$B$16^2/2)*_xlfn.NORM.S.DIST(((LN($B$18)-(E40+LN($B$17*0.5)))/$B$16)-$B$16,TRUE())+$B$18*(1-_xlfn.NORM.S.DIST(((LN($B$18)-(E40+LN($B$17*0.5)))/$B$16),TRUE())) -> 20.999999 | G40: =EXP((E40+LN($B$17*1))+$B$16^2/2)*_xlfn.NORM.S.DIST(((LN($B$19)-(E40+LN($B$17*1)))/$B$16)-$B$16,TRUE())+$B$19*(1-_xlfn.NORM.S.DIST(((LN($B$19)-(E40+LN($B$17*1)))/$B$16),TRUE())) -> 38.116496 | H40: =EXP((E40+LN($B$17*$B$5))+$B$16^2/2)*_xlfn.NORM.S.DIST(((LN($B$4)-(E40+LN($B$17*$B$5)))/$B$16)-$B$16,TRUE())+$B$4*(1-_xlfn.NORM.S.DIST(((LN($B$4)-(E40+LN($B$17*$B$5)))/$B$16),TRUE())) -> 38.116496 | I40: =H40-G40 -> 0 | J40: 232 | K40: 1713 | L40: 303 | M40: =$B$32+($B$33-$B$32)*(MIN(85,MAX(20,D40))-20)/65 -> 77.584615 | N40: 1 | O40: =IF(SUMPRODUCT($B$36:$B$44,$J$36:$J$44)>0,B47*1000000000*J40/SUMPRODUCT($B$36:$B$44,$J$36:$J$44),0) -> 0 | P40: =IF(SUMPRODUCT($B$36:$B$44,$K$36:$K$44)>0,B48*1000000000*K40/SUMPRODUCT($B$36:$B$44,$K$36:$K$44),0) -> 0 | Q40: =-$B$9*$B$24*1000000000*L40/SUMPRODUCT($B$36:$B$44,$L$36:$L$44) -> 0 | R40: =(B50+B52)*1000000000*M40/SUMPRODUCT($B$36:$B$44,$M$36:$M$44) -> 0 | S40: =B51*1000000000*N40/SUMPRODUCT($B$36:$B$44,$N$36:$N$44) -> 0 | T40: =I40+(O40+P40)*$B$26+Q40*(1-$B$25) -> 0 | U40: =(O40+P40)*(1-$B$26)+Q40*$B$25+R40 -> 0
A41: 51-60 ans | B41: 8912890 | C41: 27 | D41: 55.5 | E41: 2.653616 | F41: =EXP((E41+LN($B$17*0.5))+$B$16^2/2)*_xlfn.NORM.S.DIST(((LN($B$18)-(E41+LN($B$17*0.5)))/$B$16)-$B$16,TRUE())+$B$18*(1-_xlfn.NORM.S.DIST(((LN($B$18)-(E41+LN($B$17*0.5)))/$B$16),TRUE())) -> 26.999999 | G41: =EXP((E41+LN($B$17*1))+$B$16^2/2)*_xlfn.NORM.S.DIST(((LN($B$19)-(E41+LN($B$17*1)))/$B$16)-$B$16,TRUE())+$B$19*(1-_xlfn.NORM.S.DIST(((LN($B$19)-(E41+LN($B$17*1)))/$B$16),TRUE())) -> 47.885171 | H41: =EXP((E41+LN($B$17*$B$5))+$B$16^2/2)*_xlfn.NORM.S.DIST(((LN($B$4)-(E41+LN($B$17*$B$5)))/$B$16)-$B$16,TRUE())+$B$4*(1-_xlfn.NORM.S.DIST(((LN($B$4)-(E41+LN($B$17*$B$5)))/$B$16),TRUE())) -> 47.885171 | I41: =H41-G41 -> 0 | J41: 276 | K41: 2557 | L41: 407 | M41: =$B$32+($B$33-$B$32)*(MIN(85,MAX(20,D41))-20)/65 -> 93.892308 | N41: 1 | O41: =IF(SUMPRODUCT($B$36:$B$44,$J$36:$J$44)>0,B47*1000000000*J41/SUMPRODUCT($B$36:$B$44,$J$36:$J$44),0) -> 0 | P41: =IF(SUMPRODUCT($B$36:$B$44,$K$36:$K$44)>0,B48*1000000000*K41/SUMPRODUCT($B$36:$B$44,$K$36:$K$44),0) -> 0 | Q41: =-$B$9*$B$24*1000000000*L41/SUMPRODUCT($B$36:$B$44,$L$36:$L$44) -> 0 | R41: =(B50+B52)*1000000000*M41/SUMPRODUCT($B$36:$B$44,$M$36:$M$44) -> 0 | S41: =B51*1000000000*N41/SUMPRODUCT($B$36:$B$44,$N$36:$N$44) -> 0 | T41: =I41+(O41+P41)*$B$26+Q41*(1-$B$25) -> 0 | U41: =(O41+P41)*(1-$B$26)+Q41*$B$25+R41 -> 0
A42: 61-70 ans | B42: 7991246 | C42: 35 | D42: 65.5 | E42: 3.047169 | F42: =EXP((E42+LN($B$17*0.5))+$B$16^2/2)*_xlfn.NORM.S.DIST(((LN($B$18)-(E42+LN($B$17*0.5)))/$B$16)-$B$16,TRUE())+$B$18*(1-_xlfn.NORM.S.DIST(((LN($B$18)-(E42+LN($B$17*0.5)))/$B$16),TRUE())) -> 34.999992 | G42: =EXP((E42+LN($B$17*1))+$B$16^2/2)*_xlfn.NORM.S.DIST(((LN($B$19)-(E42+LN($B$17*1)))/$B$16)-$B$16,TRUE())+$B$19*(1-_xlfn.NORM.S.DIST(((LN($B$19)-(E42+LN($B$17*1)))/$B$16),TRUE())) -> 60.340185 | H42: =EXP((E42+LN($B$17*$B$5))+$B$16^2/2)*_xlfn.NORM.S.DIST(((LN($B$4)-(E42+LN($B$17*$B$5)))/$B$16)-$B$16,TRUE())+$B$4*(1-_xlfn.NORM.S.DIST(((LN($B$4)-(E42+LN($B$17*$B$5)))/$B$16),TRUE())) -> 60.340185 | I42: =H42-G42 -> 0 | J42: 333 | K42: 3822 | L42: 444 | M42: =$B$32+($B$33-$B$32)*(MIN(85,MAX(20,D42))-20)/65 -> 110.2 | N42: 0 | O42: =IF(SUMPRODUCT($B$36:$B$44,$J$36:$J$44)>0,B47*1000000000*J42/SUMPRODUCT($B$36:$B$44,$J$36:$J$44),0) -> 0 | P42: =IF(SUMPRODUCT($B$36:$B$44,$K$36:$K$44)>0,B48*1000000000*K42/SUMPRODUCT($B$36:$B$44,$K$36:$K$44),0) -> 0 | Q42: =-$B$9*$B$24*1000000000*L42/SUMPRODUCT($B$36:$B$44,$L$36:$L$44) -> 0 | R42: =(B50+B52)*1000000000*M42/SUMPRODUCT($B$36:$B$44,$M$36:$M$44) -> 0 | S42: =B51*1000000000*N42/SUMPRODUCT($B$36:$B$44,$N$36:$N$44) -> 0 | T42: =I42+(O42+P42)*$B$26+Q42*(1-$B$25) -> 0 | U42: =(O42+P42)*(1-$B$26)+Q42*$B$25+R42 -> 0
A43: 71-80 ans | B43: 6355648 | C43: 46 | D43: 75.5 | E43: 3.525834 | F43: =EXP((E43+LN($B$17*0.5))+$B$16^2/2)*_xlfn.NORM.S.DIST(((LN($B$18)-(E43+LN($B$17*0.5)))/$B$16)-$B$16,TRUE())+$B$18*(1-_xlfn.NORM.S.DIST(((LN($B$18)-(E43+LN($B$17*0.5)))/$B$16),TRUE())) -> 45.999991 | G43: =EXP((E43+LN($B$17*1))+$B$16^2/2)*_xlfn.NORM.S.DIST(((LN($B$19)-(E43+LN($B$17*1)))/$B$16)-$B$16,TRUE())+$B$19*(1-_xlfn.NORM.S.DIST(((LN($B$19)-(E43+LN($B$17*1)))/$B$16),TRUE())) -> 76.517324 | H43: =EXP((E43+LN($B$17*$B$5))+$B$16^2/2)*_xlfn.NORM.S.DIST(((LN($B$4)-(E43+LN($B$17*$B$5)))/$B$16)-$B$16,TRUE())+$B$4*(1-_xlfn.NORM.S.DIST(((LN($B$4)-(E43+LN($B$17*$B$5)))/$B$16),TRUE())) -> 76.517324 | I43: =H43-G43 -> 0 | J43: 452 | K43: 5587 | L43: 497 | M43: =$B$32+($B$33-$B$32)*(MIN(85,MAX(20,D43))-20)/65 -> 126.50769 | N43: 0 | O43: =IF(SUMPRODUCT($B$36:$B$44,$J$36:$J$44)>0,B47*1000000000*J43/SUMPRODUCT($B$36:$B$44,$J$36:$J$44),0) -> 0 | P43: =IF(SUMPRODUCT($B$36:$B$44,$K$36:$K$44)>0,B48*1000000000*K43/SUMPRODUCT($B$36:$B$44,$K$36:$K$44),0) -> 0 | Q43: =-$B$9*$B$24*1000000000*L43/SUMPRODUCT($B$36:$B$44,$L$36:$L$44) -> 0 | R43: =(B50+B52)*1000000000*M43/SUMPRODUCT($B$36:$B$44,$M$36:$M$44) -> 0 | S43: =B51*1000000000*N43/SUMPRODUCT($B$36:$B$44,$N$36:$N$44) -> 0 | T43: =I43+(O43+P43)*$B$26+Q43*(1-$B$25) -> 0 | U43: =(O43+P43)*(1-$B$26)+Q43*$B$25+R43 -> 0
A44: 80 ans ou plus | B44: 3975523 | C44: 52 | D44: 85 | E44: 3.773603 | F44: =EXP((E44+LN($B$17*0.5))+$B$16^2/2)*_xlfn.NORM.S.DIST(((LN($B$18)-(E44+LN($B$17*0.5)))/$B$16)-$B$16,TRUE())+$B$18*(1-_xlfn.NORM.S.DIST(((LN($B$18)-(E44+LN($B$17*0.5)))/$B$16),TRUE())) -> 52.000003 | G44: =EXP((E44+LN($B$17*1))+$B$16^2/2)*_xlfn.NORM.S.DIST(((LN($B$19)-(E44+LN($B$17*1)))/$B$16)-$B$16,TRUE())+$B$19*(1-_xlfn.NORM.S.DIST(((LN($B$19)-(E44+LN($B$17*1)))/$B$16),TRUE())) -> 84.911137 | H44: =EXP((E44+LN($B$17*$B$5))+$B$16^2/2)*_xlfn.NORM.S.DIST(((LN($B$4)-(E44+LN($B$17*$B$5)))/$B$16)-$B$16,TRUE())+$B$4*(1-_xlfn.NORM.S.DIST(((LN($B$4)-(E44+LN($B$17*$B$5)))/$B$16),TRUE())) -> 84.911137 | I44: =H44-G44 -> 0 | J44: 638 | K44: 7858 | L44: 434 | M44: =$B$32+($B$33-$B$32)*(MIN(85,MAX(20,D44))-20)/65 -> 142 | N44: 0 | O44: =IF(SUMPRODUCT($B$36:$B$44,$J$36:$J$44)>0,B47*1000000000*J44/SUMPRODUCT($B$36:$B$44,$J$36:$J$44),0) -> 0 | P44: =IF(SUMPRODUCT($B$36:$B$44,$K$36:$K$44)>0,B48*1000000000*K44/SUMPRODUCT($B$36:$B$44,$K$36:$K$44),0) -> 0 | Q44: =-$B$9*$B$24*1000000000*L44/SUMPRODUCT($B$36:$B$44,$L$36:$L$44) -> 0 | R44: =(B50+B52)*1000000000*M44/SUMPRODUCT($B$36:$B$44,$M$36:$M$44) -> 0 | S44: =B51*1000000000*N44/SUMPRODUCT($B$36:$B$44,$N$36:$N$44) -> 0 | T44: =I44+(O44+P44)*$B$26+Q44*(1-$B$25) -> 0 | U44: =(O44+P44)*(1-$B$26)+Q44*$B$25+R44 -> 0
A45: Levier | B45: Recettes Assurance maladie (Md€) | C45: Patients (Md€) | D45: Via les primes (Md€) | E45: Employeurs (Md€) | F45: Médecins (Md€)
A46: Franchises et participations forfaitaires | B46: =SUMPRODUCT($B$36:$B$44,$I$36:$I$44)/1000000000 -> 0 | C46: =B46 -> 0 | D46: =0 -> 0 | E46: =0 -> 0 | F46: =0 -> 0
A47: Ticket modérateur des consultations | B47: =MAX(0,($B$6-$B$20)*100*$B$21) -> 0 | C47: =B47*$B$26 -> 0 | D47: =B47*(1-$B$26) -> 0 | E47: =0 -> 0 | F47: =0 -> 0
...

Sheet Sources
A1: Sources
A3: Donnée | B3: Source | C3: Lien
A4: Taux d'effort, bouclier | B4: Drees, Études et Résultats n° 1345, juillet 2025, encadré 3 et tableaux complémentaires A et G (Ines-Omar 2019) | C4: https://drees.solidarites-sante.gouv.fr/publications-communique-de-presse/250828_ER_depenses-de-sante
A5: Taux d'effort par niveau de vie | B5: Drees, Études et Résultats n° 1345, juillet 2025, tableau complémentaire C (modèle Ines-Omar 2019) | C5: https://drees.solidarites-sante.gouv.fr/publications-communique-de-presse/250828_ER_depenses-de-sante
A6: Déficit de la branche maladie | B6: Commission des comptes de la sécurité sociale, rapport de mai 2026 | C6: https://www.securite-sociale.fr/files/live/sites/SSFR/files/medias/CCSS/2026/CCSS%20mai%202026_assembl%C3%A9_V2.pdf
A7: Cotisation maladie sur les complémentaires | B7: Question écrite n° 161 à l'Assemblée nationale, 8 octobre 2024 ; service-public.gouv.fr (prélèvements sur les pensions) | C7: https://questions.assemblee-nationale.fr/q17/17-161QE.htm
A8: Ménages | B8: Insee Première n° 1875, 2021 (champ de 63,4 millions de personnes) | C8: https://www.insee.fr/fr/statistiques/5431993
A9: CSG des retraités | B9: Code de la sécurité sociale, art. L136-8 ; seuils 2025 : service-public.gouv.fr | C9: https://www.service-public.gouv.fr/particuliers/vosdroits/F2971
A10: Part des pensions de base | B10: IPP, Perspectives budgétaires 2027, chapitre 3 : sous-indexation des retraites (Aubert, Tô, Tochev, 2026) | C10: https://www.ipp.eu/wp-content/uploads/2026/07/Chapitre_Desindexation_retraite___Rapport_Perspectives_Budgetaires_2027-4.pdf
A11: Composition des revenus | B11: COR, rapport annuel juin 2026, figure 3.8 : pensions 77,8 % du revenu des ménages retraités, revenus d'activité 84,1 % de celui des ménages actifs
A12: Franchises et participations | B12: Décret n° 2026-858 du 11 septembre 2026 (service-public.gouv.fr, 16 septembre 2026) | C12: https://www.service-public.gouv.fr/particuliers/actualites/A17166
A13: Dépenses et restes à charge par âge | B13: Drees, dépenses de santé et restes à charge 2023 (données de l'Assurance maladie) | C13: https://data.drees.solidarites-sante.gouv.fr/explore/dataset/depenses-de-sante-et-restes-a-charge/information/
A14: Ticket modérateur des consultations | B14: PLFSS 2025, mesure de transfert du ticket modérateur des consultations (1,1 Md€ pour 10 points), citée par Previssima et Public Sénat | C14: https://www.publicsenat.fr/actualites/sante/consultations-medicales-la-ministre-de-la-sante-tempere-sur-la-hausse-du-ticket-moderateur
A15: Hausses du ticket modérateur de 2027 | B15: JORF du 22 août 2026, décrets n° 2026-809 à 2026-812 ; montant : presse spécialisée (SPAC Actuaires, Caducée) | C15: https://www.legifrance.gouv.fr/jorf/jo/2026/08/22/0195
A16: ALD | B16: CCSS, mai 2026, fiche 2.2 (mesures d'économies abandonnées en LFSS 2026) | C16: https://www.securite-sociale.fr/files/live/sites/SSFR/files/medias/CCSS/2026/CCSS%20mai%202026_assembl%C3%A9_V2.pdf
A17: Dépassements d'honoraires | B17: Rapport de la mission Rousset-Monnet sur les dépassements d'honoraires, octobre 2025 | C17: https://www.apmnews.com/documents/202510231649030.rapport_consolide_depassements_dhonoraires_VF_compressed.pdf
A18: TSA | B18: Code de la sécurité sociale, art. L862-4 ; recettes : CCSS, mai 2026 (impôts et taxes affectés) | C18: https://www.legifrance.gouv.fr/codes/article_lc/LEGIARTI000042698839
A19: Contrats d'entreprise | B19: PLFSS 2026, annexe 4, tableau 9 (coût des exemptions d'assiette) | C19: https://www.assemblee-nationale.fr/dyn/contenu/visualisation/1088679/file/PLFSS2026-Annexe4-20251014-183718-59-11_avec%20couverture-2.pdf
A20: Primes par âge | B20: Drees, enquête auprès des organismes complémentaires, données 2023 (septembre 2025) | C20: https://drees.solidarites-sante.gouv.fr/communique-de-presse-jeux-de-donnees/jeux-de-donnees/250923_DATA_organismes-couvertures-compl%C3%A9mentaires-sant%C3%A9

Sheet Vérification
A1: Vérification des chiffres
A2: Chaque chiffre saisi dans ce classeur, revérifié à la source en octobre 2026.
A4: Donnée | B4: Valeur | C4: Type | D4: Comment c'est calculé | E4: Source | F4: Lien | G4: Statut | H4: Remarque
A5: Taux d'effort pour la santé par niveau de vie, actifs et retraités | B5: 2019 | C5: Chiffre publié | D5: Tableau complémentaire C, repris à l'identique. | E5: Drees, Études et Résultats n° 1345 (2025) | F5: https://drees.solidarites-sante.gouv.fr/publications-communique-de-presse/250828_ER_depenses-de-sante | G5: Confirmé
A6: Taux d'effort en primes et restes à charge par dixième et tops, composition des groupes | B6: 2019 | C6: Chiffre publié | D6: Encadré 3 et tableaux complémentaires A et G, repris à l'identique. | E6: Drees, Études et Résultats n° 1345 (2025) | F6: https://drees.solidarites-sante.gouv.fr/publications-communique-de-presse/250828_ER_depenses-de-sante | G6: Confirmé
A7: Part des retraités de chaque niveau de vie exposée aux taux normal et médian | B7: 0 à 100 % | C7: Hypothèse du site | D7: Déduite des seuils de CSG : taux normal vers 2 400 € de pension brute pour une personne seule, taux médian vers 1 550 €. | E7: Hypothèse du site | G7: Estimation, non vérifiable
A8: Assiettes des pensions aux taux normal et médian | B8: 190,5 et 118,7 Md€ | C8: Calcul du site | D8: Calées sur l'IPP (voir le classeur Retraites). | E8: IPP, note n° 129 (2026) | F8: https://www.ipp.eu/publication/comment-mettre-a-contribution-les-retraites-pour-le-redressement-des-finances-publiques/ | G8: Confirmé
A9: Part de la pension venant des régimes de base | B9: 67 % | C9: Calcul du site | D9: 6,6 Md€ économisés par un gel de 2,5 % ÷ 0,025 = 264 Md€ de pensions de base, sur ≈ 400 Md€. | E9: IPP, note n° 129 et chapitre 3 (2026) | F9: https://www.ipp.eu/publication/comment-mettre-a-contribution-les-retraites-pour-le-redressement-des-finances-publiques/ | G9: Confirmé
A10: Solde de la branche maladie du régime général, 2026 | B10: −13,8 Md€ | C10: Chiffre publié | D10: Repris tel quel. | E10: CCSS, rapport de mai 2026 | F10: https://www.securite-sociale.fr/files/live/sites/SSFR/files/medias/CCSS/2026/CCSS%20mai%202026_assembl%C3%A9_V2.pdf | G10: Confirmé
A11: Cotisation maladie sur les retraites complémentaires | B11: 1 % | C11: Loi ou barème | D11: Retraités au taux médian ou normal de CSG. | E11: Question écrite n° 161 (2024) ; service-public.gouv.fr | F11: https://questions.assemblee-nationale.fr/q17/17-161QE.htm | G11: Confirmé
A12: Ménages dans le champ de l'enquête | B12: 28,8 millions | C12: Calcul du site | D12: 63,4 millions de personnes ÷ 2,2 personnes par ménage. | E12: Insee Première n° 1875 ; Insee, ménages | F12: https://www.insee.fr/fr/statistiques/5431993 | G12: Confirmé
A13: Évolution 2019 → 2024 des dépenses payées par les complémentaires et les ménages | B13: × 1,186 | C13: Calcul du site | D13: (32,52 + 19,96) ÷ (26,74 + 17,52) Md€. | E13: Drees, comptes de la santé (données en ligne) | F13: https://data.drees.solidarites-sante.gouv.fr/explore/dataset/cns_financement/information/ | G13: Confirmé
A14: Part des pensions dans le revenu des retraités ; répartition par taux de CSG | B14: 77,8 % ; 29 / 27 % | C14: Calcul du site | D14: Voir le classeur Retraites. | E14: COR 2026, figure 3.8 ; Cnav | F14: https://www.cor-retraites.fr/sites/default/files/2026-06/RA_2026_def.pdf | G14: Confirmé
A15: Franchises (1 € par boîte et acte paramédical, 4 € par transport) et participations (2 €) ; plafonds annuels | B15: 70 € + 70 € depuis le 1er octobre 2026 | C15: Loi ou barème | D15: Plafonds relevés de 50 € à 70 € chacun ; montants unitaires inchangés. | E15: Décret n° 2026-858 du 11 septembre 2026 (service-public.gouv.fr) | F15: https://www.service-public.gouv.fr/particuliers/actualites/A17166 | G15: Confirmé
A16: Doublement des franchises, participations et plafonds (PLFSS 2026, abandonné) | B16: 2,3 Md€ | C16: Chiffre publié | D16: Point de contrôle du modèle (retrouvé à 5 % près). | E16: CCSS, mai 2026, fiche 2.2 | F16: https://www.securite-sociale.fr/files/live/sites/SSFR/files/medias/CCSS/2026/CCSS%20mai%202026_assembl%C3%A9_V2.pdf | G16: Confirmé
A17: Doublement des seuls plafonds (100 € + 100 €) | B17: ≈ 0,75 Md€ | C17: Chiffre publié | D17: Point de contrôle du modèle ; chiffre annoncé par le gouvernement en juillet 2026. | E17: Public Sénat, Caducée (juillet-septembre 2026) | G17: Confirmé (source secondaire) | H17: Le rendement du décret finalement pris (70 € + 70 €) n'a pas été publié.
A18: Franchises et participations payées par personne et par âge | B18: 0 à 52 € (2023) | C18: Chiffre publié | D18: Repris tel quel ; sert à caler le modèle par âge. | E18: Drees, dépenses de santé et restes à charge 2023 | F18: https://data.drees.solidarites-sante.gouv.fr/explore/dataset/depenses-de-sante-et-restes-a-charge/information/ | G18: Confirmé
A19: Dispersion du modèle de franchises (log-normale) | B19: 1,4 | C19: Hypothèse du site | D19: Choisie pour retrouver les deux points de contrôle officiels. | E19: Hypothèse du site | G19: Estimation, non vérifiable
A20: Ticket modérateur des consultations : rendement d'un point | B20: 0,11 Md€ | C20: Calcul du site | D20: 1,1 Md€ transférés aux complémentaires pour 30 → 40 % (PLFSS 2025) ÷ 10. | E20: PLFSS 2025, mesure citée par Public Sénat et Previssima | F20: https://www.publicsenat.fr/actualites/sante/consultations-medicales-la-ministre-de-la-sante-tempere-sur-la-hausse-du-ticket-moderateur | G20: Confirmé (source secondaire)
A21: Hausses du ticket modérateur de 2027 (dentaire, dispositifs, médicaments, transports) | B21: ≈ 1,5 Md€ | C21: Chiffre publié | D21: Décrets publiés au JO du 22 août 2026 ; montant tiré de la presse spécialisée. Non compté (déjà décidé). | E21: Décrets n° 2026-809 à 812 | F21: https://www.legifrance.gouv.fr/jorf/jo/2026/08/22/0195 | G21: Confirmé (source secondaire)
A22: ALD : cures thermales alignées (0,2 Md€), fin des ALD « non exonérantes » (0,1 Md€) | B22: 0,3 Md€ | C22: Chiffre publié | D22: Mesures du PLFSS 2026 abandonnées en LFSS. | E22: CCSS, mai 2026, fiche 2.2 | F22: https://www.securite-sociale.fr/files/live/sites/SSFR/files/medias/CCSS/2026/CCSS%20mai%202026_assembl%C3%A9_V2.pdf | G22: Confirmé
A23: Dépassements d'honoraires 2024 ; part remboursée par les complémentaires | B23: 4,5 Md€ ; 37 à 40 % | C23: Chiffre publié | D23: Repris tel quel (milieu retenu : 38,5 %). | E23: Mission Rousset-Monnet (octobre 2025) | F23: https://www.apmnews.com/documents/202510231649030.rapport_consolide_depassements_dhonoraires_VF_compressed.pdf | G23: Confirmé
A24: Part de la population sans complémentaire santé | B24: 5 % | C24: Chiffre publié | D24: Repris tel quel. | E24: Mission Rousset-Monnet (octobre 2025) | F24: https://www.apmnews.com/documents/202510231649030.rapport_consolide_depassements_dhonoraires_VF_compressed.pdf | G24: Confirmé
A25: Taxe de solidarité additionnelle : taux ; recettes 2025 | B25: 13,27 % ; 6,558 Md€ | C25: Loi ou barème | D25: Valeur d'un point : 6,558 ÷ 13,27 ≈ 0,49 Md€ (un peu forte : certains contrats sont taxés à 20,27 %). | E25: CSS, art. L862-4 ; CCSS, mai 2026 | F25: https://www.legifrance.gouv.fr/codes/article_lc/LEGIARTI000042698839 | G25: Confirmé
A26: Contrats santé et prévoyance d'entreprise : assiette exemptée ; manque à gagner net ; forfait social | B26: 24,3 Md€ ; 5,6 Md€ ; 8 % | C26: Chiffre publié | D26: Prévision 2026, tableau 9 (santé et prévoyance ensemble). | E26: PLFSS 2026, annexe 4 | F26: https://www.assemblee-nationale.fr/dyn/contenu/visualisation/1088679/file/PLFSS2026-Annexe4-20251014-183718-59-11_avec%20couverture-2.pdf | G26: Confirmé
A27: Prime mensuelle de complémentaire à 20 et 85 ans | B27: 36 € ; 142 € | C27: Chiffre publié | D27: Interpolée linéairement entre ces âges pour répartir une hausse de primes. | E27: Drees, organismes complémentaires (2025) | F27: https://drees.solidarites-sante.gouv.fr/communique-de-presse-jeux-de-donnees/jeux-de-donnees/250923_DATA_organismes-couvertures-compl%C3%A9mentaires-sant%C3%A9 | G27: Confirmé
A29: Types : « Chiffre publié » (repris d'une publication), « Lu sur un graphique », « Calcul du site » (formule à partir de chiffres publiés), « Hypothèse du site », « Loi ou barème ».
A30: Statuts : « Confirmé » (vérifié à la source primaire), « Corrigé » (valeur changée lors de cette vérification), « Confirmé (source secondaire) », « Estimation, non vérifiable ».
