Workbook

Sheet Lisez-moi
A1: Chiffrage de l'espace Héritage
A2: La grande transmission : https://bonquentin-collab.github.io/Create-Website/
A4: Contenu
A5: Hypothèses : choix du scénario (« Étude 2024 » ou « Actualisé 2026 ») et hypothèses modifiables. Une valeur saisie dans la colonne « Votre valeur » remplace celle du scénario.
A6: Modèle IGS : flux successoral, droits actuels, pilier 1 et pilier 2, année par année (2021-2040), et résultats 2025-2040. Mêmes formules que le classeur de l'étude de la Fondation Jean-Jaurès (2024) et que le site.
A7: Calcul individuel : impôt d'un héritier en ligne directe, droit actuel contre barème de l'IGS.
A8: Gain salaire : ce que rapporterait à un actif une part des recettes de l'IGS (variante du site, l'étude ne la propose pas).
A9: Sources : références de chaque donnée.
A10: Vérification
A11: Avec les hypothèses par défaut, chaque résultat est identique à celui du site (écart < 0,01 Md€ pour les recettes, < 1 € pour les montants individuels).
A12: Limites
A13: L'étude mêle euros courants et croissances réelles (PIB +1 %/an sans inflation) ; la part du top 1 % du patrimoine y passe de 24 % à 35 % en 2040 ; aucun effet de comportement (exil, optimisation, étalement du paiement).
... A20: Fond vert pâle : résultat principal

Sheet Hypothèses
A1: Hypothèses du chiffrage de l'IGS
A2: Choisissez le scénario en B4 ; saisissez une valeur en colonne D pour la remplacer.
A4: Scénario actif | B4: Actualisé 2026 | C4: =IF(B4="Étude 2024",1,2) -> 2 | D4: ← 1 = étude, 2 = actualisé
A6: Hypothèse | B6: Étude 2024 | C6: Actualisé 2026 | D6: Votre valeur | E6: Valeur retenue | F6: Source
A7: Croissance annuelle du PIB (après la dernière année connue) | B7: 0.01 | C7: 0.01 | E7: =IF(ISBLANK(D7),IF($C$4=1,B7,C7),D7) -> 0.01 | F7: Étude : +1 % par an
A8: Flux successoral en 2050 (part du PIB) | B8: 0.23 | C8: 0.23 | E8: =IF(ISBLANK(D8),IF($C$4=1,B8,C8),D8) -> 0.23 | F8: CAE, note n° 63, 2021 (d'après Goupille-Lebret et al.)
A9: Croissance annuelle du patrimoine du top 1 % | B9: 0.041 | C9: 0.041 | E9: =IF(ISBLANK(D9),IF($C$4=1,B9,C9),D9) -> 0.041 | F9: Garbinti, Goupille-Lebret et Piketty (2021) : 6,10 % par an en moyenne sur 2005-2014, moins 2 % d'inflation
A10: Part de plus-values latentes dans le patrimoine du top 1 % | B10: 0.41251954 | C10: 0.41251954 | E10: =IF(ISBLANK(D10),IF($C$4=1,B10,C10),D10) -> 0.41251954 | F10: Saez et al. (2021) : 17 681 Md€ de plus-values latentes sur 42 861 Md€ de patrimoine du top 1 %
A11: Taux du PFU | B11: 0.3 | C11: 0.314 | E11: =IF(ISBLANK(D11),IF($C$4=1,B11,C11),D11) -> 0.314 | F11: PFU de 30 % (2024) / PFU de 31,4 % depuis le 1er janvier 2026 (12,8 % d'impôt + 18,6 % de prélèvements sociaux, LFSS 2026)
A12: Flux successoral en 2021 (part du PIB) | B12: 0.15 | C12: 0.15 | E12: =IF(ISBLANK(D12),IF($C$4=1,B12,C12),D12) -> 0.15 | F12: CAE, note n° 63, 2021 (d'après Goupille-Lebret et al.)
A13: Année de départ du flux | B13: 2021 | C13: 2021 | E13: =IF(ISBLANK(D13),IF($C$4=1,B13,C13),D13) -> 2021
A14: Année cible du flux | B14: 2050 | C14: 2050 | E14: =IF(ISBLANK(D14),IF($C$4=1,B14,C14),D14) -> 2050
A15: Pilier 1 : recettes supplémentaires en 2021 (Md€) | B15: 10 | C15: 10 | E15: =IF(ISBLANK(D15),IF($C$4=1,B15,C15),D15) -> 10 | F15: CAE (2021), simulation de la réforme de l'assiette et du barème, reprise par l'étude
A16: Part du patrimoine détenue par le top 1 % (année de référence) | B16: 0.24 | C16: 0.24 | E16: =IF(ISBLANK(D16),IF($C$4=1,B16,C16),D16) -> 0.24 | F16: World Inequality Database, 2022
A17: Année de référence du patrimoine du top 1 % | B17: 2022 | C17: 2022 | E17: =IF(ISBLANK(D17),IF($C$4=1,B17,C17),D17) -> 2022
A18: Croissance annuelle du patrimoine de l'ensemble des ménages (pour la part du top 1 %) | B18: 0.0207 | C18: 0.0207 | E18: =IF(ISBLANK(D18),IF($C$4=1,B18,C18),D18) -> 0.0207 | F18: 4,07 % − 2 % d'inflation (étude, Banque de France)
A19: Part de l'assiette taxée après abattements | B19: 0.8 | C19: 0.8 | E19: =IF(ISBLANK(D19),IF($C$4=1,B19,C19),D19) -> 0.8 | F19: Hannezo et al. (2022)
A20: Réduction pour droits de succession déjà payés | B20: 0.2 | C20: 0.2 | E20: =IF(ISBLANK(D20),IF($C$4=1,B20,C20),D20) -> 0.2 | F20: CAE (2021)
A22: Données connues par année (au-delà : projection)
A23: Donnée | B23: Année | C23: Étude 2024 | D23: Actualisé 2026 | F23: Source
A24: PIB (Md€) | B24: 2021 | C24: 2508.1023 | D24: 2508.1023 | F24: Insee jusqu'en 2023, puis +1 % par an (étude) / Insee, Les comptes de la Nation en 2025 (Insee Première n° 2105) ; puis +1 % par an comme l'étude
A25: PIB (Md€) | B25: 2022 | C25: 2655.435 | D25: 2655.435 | F25: Insee jusqu'en 2023, puis +1 % par an (étude) / Insee, Les comptes de la Nation en 2025 (Insee Première n° 2105) ; puis +1 % par an comme l'étude
A26: PIB (Md€) | B26: 2023 | C26: 2822.5 | D26: 2822.5 | F26: Insee jusqu'en 2023, puis +1 % par an (étude) / Insee, Les comptes de la Nation en 2025 (Insee Première n° 2105) ; puis +1 % par an comme l'étude
A27: PIB (Md€) | B27: 2024 | D27: 2935.3288 | F27: Insee jusqu'en 2023, puis +1 % par an (étude) / Insee, Les comptes de la Nation en 2025 (Insee Première n° 2105) ; puis +1 % par an comme l'étude
A28: PIB (Md€) | B28: 2025 | D28: 2991.1 | F28: Insee jusqu'en 2023, puis +1 % par an (étude) / Insee, Les comptes de la Nation en 2025 (Insee Première n° 2105) ; puis +1 % par an comme l'étude
A29: Droits de succession et donations actuels (Md€) | B29: 2021 | C29: 18.7 | D29: 18.7 | F29: 20,8 Md€ en 2023, puis comme le flux successoral (étude) / Évaluation des voies et moyens, PLF 2026, tome I ; puis comme le flux successoral
A30: Droits de succession et donations actuels (Md€) | B30: 2022 | C30: 18.7 | D30: 18.7 | F30: 20,8 Md€ en 2023, puis comme le flux successoral (étude) / Évaluation des voies et moyens, PLF 2026, tome I ; puis comme le flux successoral
A31: Droits de succession et donations actuels (Md€) | B31: 2023 | C31: 20.8 | D31: 20.8 | F31: 20,8 Md€ en 2023, puis comme le flux successoral (étude) / Évaluation des voies et moyens, PLF 2026, tome I ; puis comme le flux successoral
A32: Droits de succession et donations actuels (Md€) | B32: 2024 | D32: 20.9 | F32: 20,8 Md€ en 2023, puis comme le flux successoral (étude) / Évaluation des voies et moyens, PLF 2026, tome I ; puis comme le flux successoral
A33: Droits de succession et donations actuels (Md€) | B33: 2025 | D33: 20.7 | F33: 20,8 Md€ en 2023, puis comme le flux successoral (étude) / Évaluation des voies et moyens, PLF 2026, tome I ; puis comme le flux successoral
A34: Droits de succession et donations actuels (Md€) | B34: 2026 | D34: 21.4 | F34: 20,8 Md€ en 2023, puis comme le flux successoral (étude) / Évaluation des voies et moyens, PLF 2026, tome I ; puis comme le flux successoral
A35: Patrimoine net des ménages (Md€) | B35: 2022 | C35: 13837.631 | D35: 14760.494 | F35: Banque de France, patrimoine net des ménages (étude) / Insee Première n° 2081, Le patrimoine économique national en 2024 (ménages, ISBLSM comprises)
A36: Patrimoine net des ménages (Md€) | B36: 2023 | C36: 13642.866 | D36: 14849.057 | F36: Banque de France, patrimoine net des ménages (étude) / Insee Première n° 2081, Le patrimoine économique national en 2024 (ménages, ISBLSM comprises)
A37: Patrimoine net des ménages (Md€) | B37: 2024 | D37: 14953 | F37: Banque de France, patrimoine net des ménages (étude) / Insee Première n° 2081, Le patrimoine économique national en 2024 (ménages, ISBLSM comprises)
A39: Mortalité du top 1 % (Insee 2021 et rapport du CPO sur les assujettis à l'ISF)
A40: Taux de mortalité | B40: 2025 | C40: 0.0223
A41: Taux de mortalité | B41: 2026 | C41: 0.0225
A42: Taux de mortalité | B42: 2027 | C42: 0.0227
A43: Taux de mortalité | B43: 2028 | C43: 0.0229
A44: Taux de mortalité | B44: 2029 | C44: 0.0231
...

Sheet Modèle IGS
A1: Modèle de chiffrage de l'IGS, année par année
A2: Md€. Formules du classeur de l'étude ; données connues lues dans « Hypothèses » selon le scénario actif.
A4: Résultats 2025-2040
A5: Scénario actif | D5: =Hypothèses!B4 -> Actualisé 2026 | G5: Part du top 1 % en 2040 | J5: =I33 -> 0.35182532
A6: Recettes supplémentaires en 2025 | D6: =M18 -> 20.190985
A7: Cumul 2025-2040 | D7: =SUM(M18:M33) -> 427.47703
A8: dont pilier 1 | D8: =SUM(F18:F33) -> 250.14122
A9: dont pilier 2 | D9: =SUM(L18:L33) -> 177.33581
A10: Moyenne annuelle | D10: =AVERAGE(M18:M33) -> 26.717314
A11: Flux successoral cumulé 2025-2040 | D11: =SUM(D18:D33) -> 9410.6967
A12: Taux effectif 2025 : aujourd'hui → avec la réforme | D12: =TEXT(E18/D18,"0.0%")&" → "&TEXT(N18/D18,"0.0%") -> 4.3% → 8.5%
A13: Année | B13: PIB | C13: Part du PIB transmise | D13: Flux successoral | E13: DMTG actuels | F13: Pilier 1 | G13: Patrimoine des ménages | H13: Patrimoine du top 1 % | I13: Part du top 1 % | J13: Mortalité | K13: Assiette plus-values | L13: Pilier 2 | M13: Recettes IGS (P1+P2) | N13: DMTG avec réforme
A14: 2021 | B14: =IF(Hypothèses!$C$4=1,Hypothèses!$C$24,Hypothèses!$D$24) -> 2508.1023 | C14: =Hypothèses!$E$12+(Hypothèses!$E$8-Hypothèses!$E$12)*(A14-Hypothèses!$E$13)/(Hypothèses!$E$14-Hypothèses!$E$13) -> 0.15 | D14: =B14*C14 -> 376.21535 | E14: =IF(Hypothèses!$C$4=1,Hypothèses!$C$29,Hypothèses!$D$29) -> 18.7
A15: 2022 | B15: =IF(Hypothèses!$C$4=1,IF(ISBLANK(Hypothèses!$C$25),B14*(1+Hypothèses!$E$7),Hypothèses!$C$25),IF(ISBLANK(Hypothèses!$D$25),B14*(1+Hypothèses!$E$7),Hypothèses!$D$25)) -> 2655.435 | C15: =Hypothèses!$E$12+(Hypothèses!$E$8-Hypothèses!$E$12)*(A15-Hypothèses!$E$13)/(Hypothèses!$E$14-Hypothèses!$E$13) -> 0.15275862 | D15: =B15*C15 -> 405.64059 | E15: =IF(Hypothèses!$C$4=1,IF(ISBLANK(Hypothèses!$C$30),E14*D15/D14,Hypothèses!$C$30),IF(ISBLANK(Hypothèses!$D$30),E14*D15/D14,Hypothèses!$D$30)) -> 18.7 | G15: =IF(Hypothèses!$C$4=1,Hypothèses!$C$35,Hypothèses!$D$35) -> 14760.494 | H15: =Hypothèses!$E$16*$G$15*(1+Hypothèses!$E$9)^(A15-Hypothèses!$E$17) -> 3542.5185 | I15: =H15/G15 -> 0.24
A16: 2023 | B16: =IF(Hypothèses!$C$4=1,IF(ISBLANK(Hypothèses!$C$26),B15*(1+Hypothèses!$E$7),Hypothèses!$C$26),IF(ISBLANK(Hypothèses!$D$26),B15*(1+Hypothèses!$E$7),Hypothèses!$D$26)) -> 2822.5 | C16: =Hypothèses!$E$12+(Hypothèses!$E$8-Hypothèses!$E$12)*(A16-Hypothèses!$E$13)/(Hypothèses!$E$14-Hypothèses!$E$13) -> 0.15551724 | D16: =B16*C16 -> 438.94741 | E16: =IF(Hypothèses!$C$4=1,IF(ISBLANK(Hypothèses!$C$31),E15*D16/D15,Hypothèses!$C$31),IF(ISBLANK(Hypothèses!$D$31),E15*D16/D15,Hypothèses!$D$31)) -> 20.8 | G16: =IF(Hypothèses!$C$4=1,IF(ISBLANK(Hypothèses!$C$36),G15*(1+Hypothèses!$E$18),Hypothèses!$C$36),IF(ISBLANK(Hypothèses!$D$36),G15*(1+Hypothèses!$E$18),Hypothèses!$D$36)) -> 14849.057 | H16: =Hypothèses!$E$16*$G$15*(1+Hypothèses!$E$9)^(A16-Hypothèses!$E$17) -> 3687.7617 | I16: =H16/G16 -> 0.2483499
A17: 2024 | B17: =IF(Hypothèses!$C$4=1,IF(ISBLANK(Hypothèses!$C$27),B16*(1+Hypothèses!$E$7),Hypothèses!$C$27),IF(ISBLANK(Hypothèses!$D$27),B16*(1+Hypothèses!$E$7),Hypothèses!$D$27)) -> 2935.3288 | C17: =Hypothèses!$E$12+(Hypothèses!$E$8-Hypothèses!$E$12)*(A17-Hypothèses!$E$13)/(Hypothèses!$E$14-Hypothèses!$E$13) -> 0.15827586 | D17: =B17*C17 -> 464.59169 | E17: =IF(Hypothèses!$C$4=1,IF(ISBLANK(Hypothèses!$C$32),E16*D17/D16,Hypothèses!$C$32),IF(ISBLANK(Hypothèses!$D$32),E16*D17/D16,Hypothèses!$D$32)) -> 20.9 | G17: =IF(Hypothèses!$C$4=1,IF(ISBLANK(Hypothèses!$C$37),G16*(1+Hypothèses!$E$18),Hypothèses!$C$37),IF(ISBLANK(Hypothèses!$D$37),G16*(1+Hypothèses!$E$18),Hypothèses!$D$37)) -> 14953 | H17: =Hypothèses!$E$16*$G$15*(1+Hypothèses!$E$9)^(A17-Hypothèses!$E$17) -> 3838.96 | I17: =H17/G17 -> 0.2567351
A18: 2025 | B18: =IF(Hypothèses!$C$4=1,IF(ISBLANK(Hypothèses!$C$28),B17*(1+Hypothèses!$E$7),Hypothèses!$C$28),IF(ISBLANK(Hypothèses!$D$28),B17*(1+Hypothèses!$E$7),Hypothèses!$D$28)) -> 2991.1 | C18: =Hypothèses!$E$12+(Hypothèses!$E$8-Hypothèses!$E$12)*(A18-Hypothèses!$E$13)/(Hypothèses!$E$14-Hypothèses!$E$13) -> 0.16103448 | D18: =B18*C18 -> 481.67024 | E18: =IF(Hypothèses!$C$4=1,IF(ISBLANK(Hypothèses!$C$33),E17*D18/D17,Hypothèses!$C$33),IF(ISBLANK(Hypothèses!$D$33),E17*D18/D17,Hypothèses!$D$33)) -> 20.7 | F18: =Hypothèses!$E$15*D18/$D$14 -> 12.803046 | G18: =G17*(1+Hypothèses!$E$18) -> 15262.527 | H18: =Hypothèses!$E$16*$G$15*(1+Hypothèses!$E$9)^(A18-Hypothèses!$E$17) -> 3996.3573 | I18: =H18/G18 -> 0.26184113 | J18: =Hypothèses!$C$40 -> 0.0223 | K18: =H18*J18*Hypothèses!$E$10 -> 36.763233 | L18: =K18*Hypothèses!$E$11*Hypothèses!$E$19*(1-Hypothèses!$E$20) -> 7.3879394 | M18: =F18+L18 -> 20.190985 | N18: =E18+M18 -> 40.890985
A19: 2026 | B19: =B18*(1+Hypothèses!$E$7) -> 3021.011 | C19: =Hypothèses!$E$12+(Hypothèses!$E$8-Hypothèses!$E$12)*(A19-Hypothèses!$E$13)/(Hypothèses!$E$14-Hypothèses!$E$13) -> 0.1637931 | D19: =B19*C19 -> 494.82077 | E19: =IF(Hypothèses!$C$4=1,IF(ISBLANK(Hypothèses!$C$34),E18*D19/D18,Hypothèses!$C$34),IF(ISBLANK(Hypothèses!$D$34),E18*D19/D18,Hypothèses!$D$34)) -> 21.4 | F19: =Hypothèses!$E$15*D19/$D$14 -> 13.152594 | G19: =G18*(1+Hypothèses!$E$18) -> 15578.461 | H19: =Hypothèses!$E$16*$G$15*(1+Hypothèses!$E$9)^(A19-Hypothèses!$E$17) -> 4160.208 | I19: =H19/G19 -> 0.26704871 | J19: =Hypothèses!$C$41 -> 0.0225 | K19: =H19*J19*Hypothèses!$E$10 -> 38.613759 | L19: =K19*Hypothèses!$E$11*Hypothèses!$E$19*(1-Hypothèses!$E$20) -> 7.7598211 | M19: =F19+L19 -> 20.912415 | N19: =E19+M19 -> 42.312415
A20: 2027 | B20: =B19*(1+Hypothèses!$E$7) -> 3051.2211 | C20: =Hypothèses!$E$12+(Hypothèses!$E$8-Hypothèses!$E$12)*(A20-Hypothèses!$E$13)/(Hypothèses!$E$14-Hypothèses!$E$13) -> 0.16655172 | D20: =B20*C20 -> 508.18614 | E20: =E19*D20/D19 -> 21.978025 | F20: =Hypothèses!$E$15*D20/$D$14 -> 13.507852 | G20: =G19*(1+Hypothèses!$E$18) -> 15900.936 | H20: =Hypothèses!$E$16*$G$15*(1+Hypothèses!$E$9)^(A20-Hypothèses!$E$17) -> 4330.7765 | I20: =H20/G20 -> 0.27235985 | J20: =Hypothèses!$C$42 -> 0.0227 | K20: =H20*J20*Hypothèses!$E$10 -> 40.554229 | L20: =K20*Hypothèses!$E$11*Hypothèses!$E$19*(1-Hypothèses!$E$20) -> 8.1497779 | M20: =F20+L20 -> 21.65763 | N20: =E20+M20 -> 43.635656
A21: 2028 | B21: =B20*(1+Hypothèses!$E$7) -> 3081.7333 | C21: =Hypothèses!$E$12+(Hypothèses!$E$8-Hypothèses!$E$12)*(A21-Hypothèses!$E$13)/(Hypothèses!$E$14-Hypothèses!$E$13) -> 0.16931034 | D21: =B21*C21 -> 521.76933 | E21: =E20*D21/D20 -> 22.565471 | F21: =Hypothèses!$E$15*D21/$D$14 -> 13.868901 | G21: =G20*(1+Hypothèses!$E$18) -> 16230.085 | H21: =Hypothèses!$E$16*$G$15*(1+Hypothèses!$E$9)^(A21-Hypothèses!$E$17) -> 4508.3383 | I21: =H21/G21 -> 0.27777663 | J21: =Hypothèses!$C$43 -> 0.0229 | K21: =H21*J21*Hypothèses!$E$10 -> 42.588908 | L21: =K21*Hypothèses!$E$11*Hypothèses!$E$19*(1-Hypothèses!$E$20) -> 8.558667 | M21: =F21+L21 -> 22.427568 | N21: =E21+M21 -> 44.993039
A22: 2029 | B22: =B21*(1+Hypothèses!$E$7) -> 3112.5507 | C22: =Hypothèses!$E$12+(Hypothèses!$E$8-Hypothèses!$E$12)*(A22-Hypothèses!$E$13)/(Hypothèses!$E$14-Hypothèses!$E$13) -> 0.17206897 | D22: =B22*C22 -> 535.57337 | E22: =E21*D22/D21 -> 23.162468 | F22: =Hypothèses!$E$15*D22/$D$14 -> 14.235819 | G22: =G21*(1+Hypothèses!$E$18) -> 16566.048 | H22: =Hypothèses!$E$16*$G$15*(1+Hypothèses!$E$9)^(A22-Hypothèses!$E$17) -> 4693.1802 | I22: =H22/G22 -> 0.28330114 | J22: =Hypothèses!$C$44 -> 0.0231 | K22: =H22*J22*Hypothèses!$E$10 -> 44.722259 | L22: =K22*Hypothèses!$E$11*Hypothèses!$E$19*(1-Hypothèses!$E$20) -> 8.9873852 | M22: =F22+L22 -> 23.223205 | N22: =E22+M22 -> 46.385673
A23: 2030 | B23: =B22*(1+Hypothèses!$E$7) -> 3143.6762 | C23: =Hypothèses!$E$12+(Hypothèses!$E$8-Hypothèses!$E$12)*(A23-Hypothèses!$E$13)/(Hypothèses!$E$14-Hypothèses!$E$13) -> 0.17482759 | D23: =B23*C23 -> 549.60132 | E23: =E22*D23/D22 -> 23.769148 | F23: =Hypothèses!$E$15*D23/$D$14 -> 14.608689 | G23: =G22*(1+Hypothèses!$E$18) -> 16908.965 | H23: =Hypothèses!$E$16*$G$15*(1+Hypothèses!$E$9)^(A23-Hypothèses!$E$17) -> 4885.6006 | I23: =H23/G23 -> 0.28893552 | J23: =Hypothèses!$C$45 -> 0.0233 | K23: =H23*J23*Hypothèses!$E$10 -> 46.958953 | L23: =K23*Hypothèses!$E$11*Hypothèses!$E$19*(1-Hypothèses!$E$20) -> 9.4368712 | M23: =F23+L23 -> 24.045561 | N23: =E23+M23 -> 47.814709
A24: 2031 | B24: =B23*(1+Hypothèses!$E$7) -> 3175.1129 | C24: =Hypothèses!$E$12+(Hypothèses!$E$8-Hypothèses!$E$12)*(A24-Hypothèses!$E$13)/(Hypothèses!$E$14-Hypothèses!$E$13) -> 0.17758621 | D24: =B24*C24 -> 563.85626 | E24: =E23*D24/D23 -> 24.385646 | F24: =Hypothèses!$E$15*D24/$D$14 -> 14.987593 | G24: =G23*(1+Hypothèses!$E$18) -> 17258.98 | H24: =Hypothèses!$E$16*$G$15*(1+Hypothèses!$E$9)^(A24-Hypothèses!$E$17) -> 5085.9102 | I24: =H24/G24 -> 0.29468196 | J24: =Hypothèses!$C$46 -> 0.0235 | K24: =H24*J24*Hypothèses!$E$10 -> 49.303878 | L24: =K24*Hypothèses!$E$11*Hypothèses!$E$19*(1-Hypothèses!$E$20) -> 9.9081072 | M24: =F24+L24 -> 24.895701 | N24: =E24+M24 -> 49.281346
A25: 2032 | B25: =B24*(1+Hypothèses!$E$7) -> 3206.8641 | C25: =Hypothèses!$E$12+(Hypothèses!$E$8-Hypothèses!$E$12)*(A25-Hypothèses!$E$13)/(Hypothèses!$E$14-Hypothèses!$E$13) -> 0.18034483 | D25: =B25*C25 -> 578.34134 | E25: =E24*D25/D24 -> 25.012096 | F25: =Hypothèses!$E$15*D25/$D$14 -> 15.372614 | G25: =G24*(1+Hypothèses!$E$18) -> 17616.241 | H25: =Hypothèses!$E$16*$G$15*(1+Hypothèses!$E$9)^(A25-Hypothèses!$E$17) -> 5294.4325 | I25: =H25/G25 -> 0.30054269 | J25: =Hypothèses!$C$47 -> 0.0238 | K25: =H25*J25*Hypothèses!$E$10 -> 51.980554 | L25: =K25*Hypothèses!$E$11*Hypothèses!$E$19*(1-Hypothèses!$E$20) -> 10.446012 | M25: =F25+L25 -> 25.818626 | N25: =E25+M25 -> 50.830723
A26: 2033 | B26: =B25*(1+Hypothèses!$E$7) -> 3238.9327 | C26: =Hypothèses!$E$12+(Hypothèses!$E$8-Hypothèses!$E$12)*(A26-Hypothèses!$E$13)/(Hypothèses!$E$14-Hypothèses!$E$13) -> 0.18310345 | D26: =B26*C26 -> 593.05974 | E26: =E25*D26/D25 -> 25.648638 | F26: =Hypothèses!$E$15*D26/$D$14 -> 15.763837 | G26: =G25*(1+Hypothèses!$E$18) -> 17980.898 | H26: =Hypothèses!$E$16*$G$15*(1+Hypothèses!$E$9)^(A26-Hypothèses!$E$17) -> 5511.5043 | I26: =H26/G26 -> 0.30651998 | J26: =Hypothèses!$C$48 -> 0.0241 | K26: =H26*J26*Hypothèses!$E$10 -> 54.793837 | L26: =K26*Hypothèses!$E$11*Hypothèses!$E$19*(1-Hypothèses!$E$20) -> 11.01137 | M26: =F26+L26 -> 26.775207 | N26: =E26+M26 -> 52.423844
A27: 2034 | B27: =B26*(1+Hypothèses!$E$7) -> 3271.322 | C27: =Hypothèses!$E$12+(Hypothèses!$E$8-Hypothèses!$E$12)*(A27-Hypothèses!$E$13)/(Hypothèses!$E$14-Hypothèses!$E$13) -> 0.18586207 | D27: =B27*C27 -> 608.01468 | E27: =E26*D27/D26 -> 26.295408 | F27: =Hypothèses!$E$15*D27/$D$14 -> 16.161347 | G27: =G26*(1+Hypothèses!$E$18) -> 18353.102 | H27: =Hypothèses!$E$16*$G$15*(1+Hypothèses!$E$9)^(A27-Hypothèses!$E$17) -> 5737.4759 | I27: =H27/G27 -> 0.31261614 | J27: =Hypothèses!$C$49 -> 0.0244 | K27: =H27*J27*Hypothèses!$E$10 -> 57.750431 | L27: =K27*Hypothèses!$E$11*Hypothèses!$E$19*(1-Hypothèses!$E$20) -> 11.605527 | M27: =F27+L27 -> 27.766874 | N27: =E27+M27 -> 54.062282
A28: 2035 | B28: =B27*(1+Hypothèses!$E$7) -> 3304.0352 | C28: =Hypothèses!$E$12+(Hypothèses!$E$8-Hypothèses!$E$12)*(A28-Hypothèses!$E$13)/(Hypothèses!$E$14-Hypothèses!$E$13) -> 0.18862069 | D28: =B28*C28 -> 623.20941 | E28: =E27*D28/D27 -> 26.95255 | F28: =Hypothèses!$E$15*D28/$D$14 -> 16.565231 | G28: =G27*(1+Hypothèses!$E$18) -> 18733.011 | H28: =Hypothèses!$E$16*$G$15*(1+Hypothèses!$E$9)^(A28-Hypothèses!$E$17) -> 5972.7125 | I28: =H28/G28 -> 0.31883355 | J28: =Hypothèses!$C$50 -> 0.0247 | K28: =H28*J28*Hypothèses!$E$10 -> 60.857357 | L28: =K28*Hypothèses!$E$11*Hypothèses!$E$19*(1-Hypothèses!$E$20) -> 12.229894 | M28: =F28+L28 -> 28.795125 | N28: =E28+M28 -> 55.747675
A29: 2036 | B29: =B28*(1+Hypothèses!$E$7) -> 3337.0756 | C29: =Hypothèses!$E$12+(Hypothèses!$E$8-Hypothèses!$E$12)*(A29-Hypothèses!$E$13)/(Hypothèses!$E$14-Hypothèses!$E$13) -> 0.19137931 | D29: =B29*C29 -> 638.64723 | E29: =E28*D29/D28 -> 27.620204 | F29: =Hypothèses!$E$15*D29/$D$14 -> 16.975576 | G29: =G28*(1+Hypothèses!$E$18) -> 19120.785 | H29: =Hypothèses!$E$16*$G$15*(1+Hypothèses!$E$9)^(A29-Hypothèses!$E$17) -> 6217.5937 | I29: =H29/G29 -> 0.32517461 | J29: =Hypothèses!$C$51 -> 0.025 | K29: =H29*J29*Hypothèses!$E$10 -> 64.121972 | L29: =K29*Hypothèses!$E$11*Hypothèses!$E$19*(1-Hypothèses!$E$20) -> 12.885951 | M29: =F29+L29 -> 29.861528 | N29: =E29+M29 -> 57.481732
A30: 2037 | B30: =B29*(1+Hypothèses!$E$7) -> 3370.4463 | C30: =Hypothèses!$E$12+(Hypothèses!$E$8-Hypothèses!$E$12)*(A30-Hypothèses!$E$13)/(Hypothèses!$E$14-Hypothèses!$E$13) -> 0.19413793 | D30: =B30*C30 -> 654.33148 | E30: =E29*D30/D29 -> 28.298517 | F30: =Hypothèses!$E$15*D30/$D$14 -> 17.392472 | G30: =G29*(1+Hypothèses!$E$18) -> 19516.585 | H30: =Hypothèses!$E$16*$G$15*(1+Hypothèses!$E$9)^(A30-Hypothèses!$E$17) -> 6472.515 | I30: =H30/G30 -> 0.33164178 | J30: =Hypothèses!$C$52 -> 0.0253 | K30: =H30*J30*Hypothèses!$E$10 -> 67.551985 | L30: =K30*Hypothèses!$E$11*Hypothèses!$E$19*(1-Hypothèses!$E$20) -> 13.575247 | M30: =F30+L30 -> 30.967719 | N30: =E30+M30 -> 59.266235
A31: 2038 | B31: =B30*(1+Hypothèses!$E$7) -> 3404.1508 | C31: =Hypothèses!$E$12+(Hypothèses!$E$8-Hypothèses!$E$12)*(A31-Hypothèses!$E$13)/(Hypothèses!$E$14-Hypothèses!$E$13) -> 0.19689655 | D31: =B31*C31 -> 670.26556 | E31: =E30*D31/D30 -> 28.987633 | F31: =Hypothèses!$E$15*D31/$D$14 -> 17.816008 | G31: =G30*(1+Hypothèses!$E$18) -> 19920.578 | H31: =Hypothèses!$E$16*$G$15*(1+Hypothèses!$E$9)^(A31-Hypothèses!$E$17) -> 6737.8881 | I31: =H31/G31 -> 0.33823758 | J31: =Hypothèses!$C$53 -> 0.0257 | K31: =H31*J31*Hypothèses!$E$10 -> 71.43342 | L31: =K31*Hypothèses!$E$11*Hypothèses!$E$19*(1-Hypothèses!$E$20) -> 14.35526 | M31: =F31+L31 -> 32.171268 | N31: =E31+M31 -> 61.158901
A32: 2039 | B32: =B31*(1+Hypothèses!$E$7) -> 3438.1923 | C32: =Hypothèses!$E$12+(Hypothèses!$E$8-Hypothèses!$E$12)*(A32-Hypothèses!$E$13)/(Hypothèses!$E$14-Hypothèses!$E$13) -> 0.19965517 | D32: =B32*C32 -> 686.45288 | E32: =E31*D32/D31 -> 29.687702 | F32: =Hypothèses!$E$15*D32/$D$14 -> 18.246275 | G32: =G31*(1+Hypothèses!$E$18) -> 20332.934 | H32: =Hypothèses!$E$16*$G$15*(1+Hypothèses!$E$9)^(A32-Hypothèses!$E$17) -> 7014.1415 | I32: =H32/G32 -> 0.34496455 | J32: =Hypothèses!$C$54 -> 0.026 | K32: =H32*J32*Hypothèses!$E$10 -> 75.230231 | L32: =K32*Hypothèses!$E$11*Hypothèses!$E$19*(1-Hypothèses!$E$20) -> 15.118267 | M32: =F32+L32 -> 33.364543 | N32: =E32+M32 -> 63.052245
A33: 2040 | B33: =B32*(1+Hypothèses!$E$7) -> 3472.5742 | C33: =Hypothèses!$E$12+(Hypothèses!$E$8-Hypothèses!$E$12)*(A33-Hypothèses!$E$13)/(Hypothèses!$E$14-Hypothèses!$E$13) -> 0.20241379 | D33: =B33*C33 -> 702.89692 | E33: =E32*D33/D32 -> 30.398874 | F33: =Hypothèses!$E$15*D33/$D$14 -> 18.683367 | G33: =G32*(1+Hypothèses!$E$18) -> 20753.826 | H33: =Hypothèses!$E$16*$G$15*(1+Hypothèses!$E$9)^(A33-Hypothèses!$E$17) -> 7301.7213 | I33: =H33/G33 -> 0.35182532 | J33: =Hypothèses!$C$55 -> 0.0263 | K33: =H33*J33*Hypothèses!$E$10 -> 79.218302 | L33: =K33*Hypothèses!$E$11*Hypothèses!$E$19*(1-Hypothèses!$E$20) -> 15.91971 | M33: =F33+L33 -> 34.603077 | N33: =E33+M33 -> 65.001951

Sheet Calcul individuel
A1: Impôt d'un héritier en ligne directe : droit actuel et IGS
A2: Saisissez la situation en jaune. Barèmes 2024 (CGI art. 777, 779, 990 I) et barème de l'étude (CAE 2021).
G3: Calcul
A4: Patrimoine reçu, hors assurance-vie (€) | B4: 300000 | G4: Part reçue de chaque parent (€) | H4: =B4/B6 -> 150000
A5: Dont assurance-vie reçue, primes versées avant 70 ans (€) | B5: 0 | G5: Base taxable par parent (€) | H5: =MAX(0,H4-B9) -> 50000
A6: Nombre de parents dont on hérite (1 ou 2) | B6: 2 | G6: Droits de succession, total (€) | H6: =SUMPRODUCT(((H5>A15:A21)*1)*(((H5<B15:B21)*H5)+((H5>=B15:B21)*B15:B21)-A15:A21)*C15:C21)*B6 -> 16388.7
A7: Plus-values latentes comprises dans le patrimoine (€) | B7: 0 | G7: Assurance-vie reçue de chaque parent (€) | H7: =B5/B6 -> 0
G8: Base taxable assurance-vie par parent (€) | H8: =MAX(0,H7-B10) -> 0
A9: Abattement par enfant et par parent (€) | B9: 100000 | G9: Prélèvement assurance-vie, total (€) | H9: =SUMPRODUCT(((H8>A25:A26)*1)*(((H8<B25:B26)*H8)+((H8>=B25:B26)*B25:B26)-A25:A26)*C25:C26)*B6 -> 0
A10: Abattement assurance-vie par bénéficiaire et par assuré (€) | B10: 152500 | G10: Droit actuel : impôt total (€) | H10: =H6+H9 -> 16388.7
A11: PFU sur les plus-values latentes (IGS, taux de l'étude) | B11: 0.3 | G11: Somme reçue (€) | H11: =B4+B5 -> 300000
G12: IGS : impôt sur les sommes reçues (€) | H12: =SUMPRODUCT(((H11>A30:A36)*1)*(((H11<B30:B36)*H11)+((H11>=B30:B36)*B30:B36)-A30:A36)*C30:C36) -> 5000
A13: Barème en ligne directe (droit actuel) | G13: IGS : PFU sur les plus-values latentes (€) | H13: =MIN(B7,B4)*B11 -> 0
A14: Tranche de | B14: à | C14: Taux | G14: IGS : impôt total (€) | H14: =H12+H13 -> 5000
A15: 0 | B15: 8072 | C15: 0.05 | G15: Écart IGS − droit actuel (€) | H15: =H14-H10 -> -11388.7
A16: 8072 | B16: 12109 | C16: 0.1 | G16: Taux moyen, droit actuel | H16: =IF(H11>0,H10/H11,0) -> 0.054629
A17: 12109 | B17: 15932 | C17: 0.15 | G17: Taux moyen, IGS | H17: =IF(H11>0,H14/H11,0) -> 0.016666667
A18: 15932 | B18: 552324 | C18: 0.2
A19: 552324 | B19: 902838 | C19: 0.3 | G19: Hypothèses : héritage en ligne directe, sans donation antérieure ; chaque parent transmet la moitié quand on hérite des deux.
A20: 902838 | B20: 1805677 | C20: 0.4
A21: 1805677 | B21: 1e+15 | C21: 0.45
A23: Assurance-vie, art. 990 I (droit actuel)
A24: Tranche de | B24: à | C24: Taux
A25: 0 | B25: 700000 | C25: 0.2
A26: 700000 | B26: 1e+15 | C26: 0.3125
A28: Barème de l'IGS, sur toutes les sommes reçues dans la vie
A29: Tranche de | B29: à | C29: Taux
A30: 0 | B30: 200000 | C30: 0
A31: 200000 | B31: 800000 | C31: 0.05
A32: 800000 | B32: 1200000 | C32: 0.15
A33: 1200000 | B33: 2000000 | C33: 0.25
A34: 2000000 | B34: 4000000 | C34: 0.35
A35: 4000000 | B35: 6000000 | C35: 0.45
A36: 6000000 | B36: 1e+15 | C36: 0.5

Sheet Gain salaire
A1: Ce que rapporterait à un actif une part des recettes de l'IGS
A2: Variante du site : l'étude affecte les recettes à l'investissement public, pas aux ménages.
A4: Année (« Moyenne » ou 2025 à 2040) | B4: Moyenne
A5: Part des recettes versée aux actifs | B5: 0.5
A6: Votre salaire net mensuel (€) | B6: 2100
A8: Personnes en emploi | B8: 30400000 | C8: Insee, Emploi, chômage, revenus du travail, édition 2025 : 30,4 millions de personnes en emploi fin 2024
A9: Masse salariale brute (€) | B9: 1108500000000 | C9: Insee, Comptes de la Nation 2024, tableau 6.205 (salaires et traitements bruts, total branches)
A10: Ratio salaire net / brut | B10: 0.78 | C10: Hypothèse du simulateur : environ 22 % de cotisations et contributions salariales
A12: Recettes de l'IGS cette année-là (Md€) | B12: =IF(B4="Moyenne",'Modèle IGS'!D10,INDEX('Modèle IGS'!M18:M33,MATCH(VALUE(B4),'Modèle IGS'!A18:A33,0))) -> 26.717314
A13: Versé aux actifs (Md€) | B13: =B12*B5 -> 13.358657
A14: Un montant égal pour chaque actif : gain mensuel (€) | B14: =B13*1000000000/B8/12 -> 36.619126
A15: Une baisse des cotisations salariales : gain mensuel (€) | B15: =B13*1000000000*(B6*12/B10)/B9/12 -> 32.4453

Sheet Sources
A1: Sources
A3: Donnée | B3: Source | C3: Lien
A4: Étude et classeur de chiffrage | B4: Fondation Jean-Jaurès, « Face à la grande transmission, l'impôt sur les grandes successions » (Ouizille, Iberrakene, Julien-Vauzelle), novembre 2024 | C4: https://www.jean-jaures.org/publication/face-a-la-grande-transmission-limpot-sur-les-grandes-successions/
A5: Flux successoral | B5: CAE, note n° 63, 2021 (d'après Goupille-Lebret et al.)
A6: PIB 2025 | B6: Insee, Les comptes de la Nation en 2025 (Insee Première n° 2105) ; puis +1 % par an comme l'étude | C6: https://www.insee.fr/fr/statistiques/8996855
A7: Droits de succession et donations 2024-2026 | B7: Évaluation des voies et moyens, PLF 2026, tome I ; puis comme le flux successoral | C7: https://www.assemblee-nationale.fr/dyn/contenu/visualisation/1087930/file/PLF%202026%20-%20V%26M%20TI%20-%20Evaluations%20des%20recettes.pdf
A8: Patrimoine des ménages 2024 | B8: Insee Première n° 2081, Le patrimoine économique national en 2024 (ménages, ISBLSM comprises) | C8: https://www.insee.fr/fr/statistiques/8661938
A9: PFU 2026 | B9: PFU de 31,4 % depuis le 1er janvier 2026 (12,8 % d'impôt + 18,6 % de prélèvements sociaux, LFSS 2026)
A10: Part du top 1 % | B10: World Inequality Database, 2022
A11: Croissance du patrimoine du top 1 % | B11: Garbinti, Goupille-Lebret et Piketty (2021) : 6,10 % par an en moyenne sur 2005-2014, moins 2 % d'inflation
A12: Plus-values latentes | B12: Saez et al. (2021) : 17 681 Md€ de plus-values latentes sur 42 861 Md€ de patrimoine du top 1 %
A13: Barèmes du droit actuel | B13: Code général des impôts, art. 777, 779 et 990 I (montants 2024)
A14: Emploi, salaires | B14: Insee, Emploi, chômage, revenus du travail, édition 2025 : 30,4 millions de personnes en emploi fin 2024 ; Insee, Comptes de la Nation 2024, tableau 6.205 (salaires et traitements bruts, total branches) | C14: https://www.insee.fr/fr/statistiques/8574681?sommaire=8574832
