Workbook

Sheet Lisez-moi
A1: Chiffrage de l'espace Retraites
A2: La grande transmission : https://bonquentin-collab.github.io/Create-Website/
A4: Contenu
A5: Paramètres : données communes à toutes les réformes (CSG, TVA, emploi, salaires, pensions, composition des revenus), avec leurs sources.
A6: Une feuille par réforme de Retraites › Simuler : TVA sociale, CSG des retraités, Retraites sans impôts, Gel des hautes pensions, Plafond des pensions. Chaque feuille reprend les curseurs du site (cellules jaunes).
A7: Niveaux de vie : effet de chaque réforme sur le niveau de vie médian des actifs et des retraités, et cumul des réformes choisies (Oui/Non).
A8: Rendement : pensions reçues pour 100 000 € cotisés pour une génération, calé sur le TRI du COR (calcul trimestre par trimestre).
A9: Sources : références de chaque donnée.
A10: Vérification
A11: Avec les réglages par défaut du site, chaque résultat est identique à celui du site (écart inférieur à 0,01 Md€ ou à 1 €).
A12: Limites
A13: Ordres de grandeur, sans effets de comportement. Les hypothèses du site (assiettes de CSG par taux, distribution des pensions portée à 2026, composition des revenus) sont décrites à côté de chaque valeur.
... A20: Fond vert pâle : résultat principal

Sheet Paramètres
A1: Paramètres communs
A2: Données sourcées ; modifiables (texte bleu).
A4: Paramètre | B4: Valeur | C4: Source
A5: Personnes en emploi | B5: 30400000 | C5: Insee, Emploi, chômage, revenus du travail, édition 2025 : 30,4 millions de personnes en emploi fin 2024
A6: Masse salariale brute (Md€) | B6: 1108.5 | C6: Insee, Comptes de la Nation 2024, tableau 6.205 (salaires et traitements bruts, total branches)
A7: Ratio salaire net / brut | B7: 0.78 | C7: Hypothèse du simulateur : environ 22 % de cotisations et contributions salariales
A8: Taux de CSG sur les revenus d'activité | B8: 0.092 | C8: Code de la sécurité sociale, art. L136-8
A9: Assiette de la CSG d'activité (part du brut) | B9: 0.9825 | C9: 98,25 % du salaire brut
A10: Valeur d'un point de CSG sur les revenus d'activité (Md€) | B10: 12 | C10: CCSS, rapport de mai 2026, tableau 1 (recettes 2025) ; valeur du point : calcul du simulateur
A11: CSG des retraités : Exonéré | B11: 0 | C11: Code de la sécurité sociale, art. L136-8 ; seuils 2025 : service-public.gouv.fr
A12: CSG des retraités : Taux réduit, 3,8 % | B12: 0.038 | C12: Code de la sécurité sociale, art. L136-8 ; seuils 2025 : service-public.gouv.fr
A13: CSG des retraités : Taux médian, 6,6 % | B13: 0.066 | C13: Code de la sécurité sociale, art. L136-8 ; seuils 2025 : service-public.gouv.fr
A14: CSG des retraités : Taux normal, 8,3 % | B14: 0.083 | C14: Code de la sécurité sociale, art. L136-8 ; seuils 2025 : service-public.gouv.fr
A15: Assiette des pensions au taux normal (Md€, calibrée sur les recettes de CSG) | B15: 225 | C15: Estimation du site, calibrée sur les recettes de CSG 2025 (CCSS, mai 2026)
A16: Assiette des pensions au taux median (Md€, calibrée sur les recettes de CSG) | B16: 87 | C16: Estimation du site, calibrée sur les recettes de CSG 2025 (CCSS, mai 2026)
... A30: Pension moyenne nette de droit direct (€/mois) | B30: 1541 | C30: DREES, édition 2025, pension moyenne de droit direct nette, fin 2023

Sheet TVA sociale
A1: TVA sociale : une hausse de TVA dont toute la recette baisse la CSG des actifs
A4: Hausse de la TVA (points) | B4: 2
A5: Taux concernés | B5: Taux normal
A6: Part de la hausse répercutée dans les prix | B6: 1
A7: Salaire net mensuel (€) | B7: 2100
A8: Pension nette mensuelle (€) | B8: 1541
A10: Recettes (Md€) | B10: =$B$4*IF($B$5="Taux normal",Paramètres!$B$22,Paramètres!$B$23) -> 15
A11: Baisse de CSG des actifs (points) | B11: =MIN(Paramètres!$B$8*100,B10/Paramètres!$B$10) -> 1.25
A12: Hausse des prix (part du revenu) | B12: =$B$4*IF($B$5="Taux normal",Paramètres!$B$24,Paramètres!$B$25)*$B$6 -> 0.0064963504
A13: Actif : gain sur la paie (€/mois) | B13: =($B$7/Paramètres!$B$7)*Paramètres!$B$9*(B11/100) -> 33.064904
A14: Actif : hausse des prix (€/mois) | B14: =$B$7*B12 -> 13.642336
A15: Actif : solde (€/mois) | B15: =B13-B14 -> 19.422568
A16: Retraité : perte la première année (€/mois) | B16: =$B$8*B12 -> 10.010876
A17: Effet sur le niveau de vie des actifs | B17: =Paramètres!$B$27*(Paramètres!$B$9*B11/100/Paramètres!$B$7)-B12 -> 0.0067453564
A18: Effet sur le niveau de vie des retraités | B18: =-B12 -> -0.0064963504

Sheet CSG retraités
A1: CSG des retraités alignée sur celle des actifs (9,2 %), recette reversée aux actifs
A4: Retraités concernés | B4: Taux normal seulement
A5: Votre pension brute mensuelle (€) | B5: 1800
A6: Votre taux de CSG actuel | B6: normal
A7: Salaire net mensuel d'un actif (€) | B7: 2100
A9: Taux | B9: Taux actuel | C9: Assiette (Md€) | D9: Concerné | E9: Nouveau taux | F9: Recette (Md€)
A10: exonere | B10: =Paramètres!$B$11 -> 0 | C10: =0 -> 0 | D10: =IF($B$4="Taux normal seulement",IF(A10="normal",1,0),IF(A10="exonere",0,1)) -> 0 | E10: =IF(D10=1,Paramètres!$B$8,B10) -> 0 | F10: =D10*C10*(Paramètres!$B$8-B10) -> 0
A11: reduit | B11: =Paramètres!$B$12 -> 0.038 | C11: =Paramètres!$B$17 -> 27 | D11: =IF($B$4="Taux normal seulement",IF(A11="normal",1,0),IF(A11="exonere",0,1)) -> 0 | E11: =IF(D11=1,Paramètres!$B$8,B11) -> 0.038 | F11: =D11*C11*(Paramètres!$B$8-B11) -> 0
A12: median | B12: =Paramètres!$B$13 -> 0.066 | C12: =Paramètres!$B$16 -> 87 | D12: =IF($B$4="Taux normal seulement",IF(A12="normal",1,0),IF(A12="exonere",0,1)) -> 0 | E12: =IF(D12=1,Paramètres!$B$8,B12) -> 0.066 | F12: =D12*C12*(Paramètres!$B$8-B12) -> 0
A13: normal | B13: =Paramètres!$B$14 -> 0.083 | C13: =Paramètres!$B$15 -> 225 | D13: =IF($B$4="Taux normal seulement",IF(A13="normal",1,0),IF(A13="exonere",0,1)) -> 1 | E13: =IF(D13=1,Paramètres!$B$8,B13) -> 0.092 | F13: =D13*C13*(Paramètres!$B$8-B13) -> 2.025
A15: Recettes (Md€) | B15: =SUM(F10:F13) -> 2.025
A16: Baisse de CSG des actifs (points) | B16: =B15/Paramètres!$B$10 -> 0.16875
A17: Gain d'un actif (€/mois) | B17: =($B$7/Paramètres!$B$7)*Paramètres!$B$9*(B16/100) -> 4.463762
A18: Perte de votre pension (€/mois) | B18: =$B$5*MAX(0,INDEX(E10:E13,MATCH($B$6,A10:A13,0))-INDEX(B10:B13,MATCH($B$6,A10:A13,0))) -> 16.2
A19: Effet sur le niveau de vie des actifs | B19: =Paramètres!$B$27*(Paramètres!$B$9*B16/100/Paramètres!$B$7) -> 0.0017876304
A20: Effet sur le niveau de vie des retraités | B20: =-Paramètres!$B$26*B15/Paramètres!$B$28 -> -0.003938625

Sheet Sans impôts
A1: Retraites financées par leurs seules ressources « logiques »
A2: Gardée = 1 : la ressource continue de financer les retraites. Les ressources « fixes » sont toujours gardées.
A4: Part du trou comblée par une baisse des pensions (le reste : hausse des cotisations) | B4: 0.5
A5: Pension nette mensuelle (€) | B5: 1541
A6: Salaire net mensuel (€) | B6: 2100
A7: Argent public libéré reversé aux actifs (Md€ par an) | B7: 0
A9: Ressource (COR 2026, tableau 2.2) | B9: Montant (Md€) | C9: Fixe | D9: Gardée (1/0) | E9: Retirée (Md€)
A10: Cotisations des salariés, des employeurs et des indépendants | B10: 277 | C10: 1 | D10: =1 -> 1 | E10: =IF(OR(C10=1,D10=1),0,B10) -> 0
A11: État employeur : la part équivalente à une cotisation normale | B11: 21 | C11: 0 | D11: 1 | E11: =IF(OR(C11=1,D11=1),0,B11) -> 0
A12: État employeur : le complément qui équilibre le régime des fonctionnaires | B12: 28.3 | C12: 0 | D12: 0 | E12: =IF(OR(C12=1,D12=1),0,B12) -> 28.3
A13: Subventions d'équilibre aux régimes spéciaux (SNCF, RATP, mines, marins…) | B13: 7.7 | C13: 0 | D13: 0 | E13: =IF(OR(C13=1,D13=1),0,B13) -> 7.7
A14: CSG affectée aux retraites | B14: 21.9 | C14: 0 | D14: 0 | E14: =IF(OR(C14=1,D14=1),0,B14) -> 21.9
A15: Forfait social et taxe sur les salaires | B15: 17.9 | C15: 0 | D15: 1 | E15: =IF(OR(C15=1,D15=1),0,B15) -> 0
A16: TVA et taxes sur la consommation | B16: 17.4 | C16: 0 | D16: 0 | E16: =IF(OR(C16=1,D16=1),0,B16) -> 17.4
A17: Autres impôts et taxes affectés | B17: 7.4 | C17: 0 | D17: 0 | E17: =IF(OR(C17=1,D17=1),0,B17) -> 7.4
A18: Transferts de la branche famille (trimestres des parents au foyer) | B18: 11.2 | C18: 0 | D18: 1 | E18: =IF(OR(C18=1,D18=1),0,B18) -> 0
A19: Transferts de l'assurance chômage (trimestres de chômage) | B19: 3.9 | C19: 0 | D19: 1 | E19: =IF(OR(C19=1,D19=1),0,B19) -> 0
A20: Autres transferts | B20: 1.3 | C20: 0 | D20: 0 | E20: =IF(OR(C20=1,D20=1),0,B20) -> 1.3
A21: Produits financiers et autres produits | B21: 7 | C21: 1 | D21: =1 -> 1 | E21: =IF(OR(C21=1,D21=1),0,B21) -> 0
A23: Ressources retirées : le trou à combler (Md€) | B23: =SUM(E10:E21) -> 84
A24: Comblé par la baisse des pensions (Md€) | B24: =B23*$B$4 -> 42
A25: Comblé par la hausse des cotisations (Md€) | B25: =B23-B24 -> 42
A26: Baisse des pensions | B26: =B24/Paramètres!$B$29 -> 0.09947892
A27: Hausse des cotisations (points de salaire brut) | B27: =B25/Paramètres!$B$6 -> 0.037889039
A28: Pension après (€/mois) | B28: =$B$5*(1-B26) -> 1387.703
A29: Perte sur le salaire (€/mois) | B29: =$B$6/Paramètres!$B$7*B27 -> 102.00895
A30: Effet sur le niveau de vie des actifs | B30: =Paramètres!$B$27*(-B27/Paramètres!$B$7+$B$7/(Paramètres!$B$6*Paramètres!$B$7)) -> -0.040852156
A31: Effet sur le niveau de vie des retraités | B31: =-Paramètres!$B$26*B26 -> -0.0773946

Sheet Gel
A1: Gel de la revalorisation des pensions au-delà d'un seuil
A2: Calé sur l'IPP (2026) : pension de base = deux tiers, économie nette des finances publiques, taux d'annuité.
A4: Seuil de pension totale brute (€/mois) | B4: 2000
A5: Revalorisation non versée | B5: 0.009
A6: Ce qui n'est pas revalorisé | B6: Toute la pension
A7: Part de la pension venant des régimes de base | B7: 0.67
A8: Appliquer aussi aux futurs retraités (taux d'annuité) | B8: Non
A9: Votre pension brute mensuelle totale (€) | B9: 2500
A10: Salaire net d'un actif (€/mois) | B10: 2100
A12: Retraités de droit direct | B12: 17300000 | C12: Drees, effectifs de retraités fin 2024 (17,3 millions de retraités de droit direct, dont 16,4 en France)
A13: Passage des euros 2020 aux pensions 2026 | B13: 1.19 | C13: Estimation du site (COR, figure 3.25 ; revalorisations 2025-2026)
A14: Pension moyenne de la tranche ouverte « 4 500 € et plus » (€ 2020) | B14: 6000 | C14: Estimation du site, cohérente avec la pension moyenne totale fin 2020
A15: Économie nette / économie des régimes (finances publiques) | B15: 0.78 | C15: IPP, Perspectives budgétaires 2027, chapitre 3 : sous-indexation des retraites (Aubert, Tô, Tochev, 2026) : « environ 20 % à 25 % » de moins
A16: Sortie annuelle des retraités actuels (décès) | B16: 0.03 | C16: Insee Première n° 2087, Bilan démographique 2025
A17: Horizon (années après 2026) | B17: 10 | C17: 2036
A18: Taux plein | B18: 0.5 | C18: Régime général
A19: Trimestres requis | B19: 172 | C19: Générations nées à partir de 1965
A20: Prélèvements sur une pension au taux normal (CSG, CRDS, Casa) | B20: 0.091 | C20: 8,3 % + 0,5 % + 0,3 %
A21: Taux d'épargne des ménages de 70 ans ou plus | B21: 0.218 | C21: Insee Première n° 1815, 2020 (enquête Budget de famille 2017)
A23: Résultats
A24: Part des retraités au-dessus du seuil | B24: =G97 -> 0.4125395
A25: Retraités concernés | B25: =G97*$B$12 -> 7136933.3
A26: Économie des régimes, première année (Md€) | B26: =$B$12*12*IF($B$6="Toute la pension",H97,I97)*$B$7*$B$5/1000000000 -> 1.5677174
A27: Gain net pour les finances publiques (Md€) | B27: =B26*$B$15 -> 1.2228196
A28: Économie la dernière année de l'horizon (Md€) | B28: =IF($B$8="Oui",B26,B26*(1-$B$16)^$B$17) -> 1.1560726
A29: Cumul sur l'horizon, première année comprise (Md€) | B29: =IF($B$8="Oui",B26*($B$17+1),B26*(1-(1-$B$16)^($B$17+1))/$B$16) -> 14.877565
A30: Votre perte (€ brut par mois) | B30: =IF($B$9<=$B$4,0,IF($B$6="Toute la pension",$B$9,$B$9-$B$4)*$B$7*$B$5) -> 15.075
A31: Valeur d'un trimestre aujourd'hui (part du salaire de référence) | B31: =$B$18/$B$19 -> 0.0029069767
A32: Valeur d'un trimestre pour un futur retraité concerné | B32: =IF($B$6="Toute la pension",B31*(1-$B$5),IF($B$9>$B$4,B31*(1-$B$5*($B$9-$B$4)/$B$9),"sous le seuil")) -> 0.002880814
A33: Baisse de CSG des actifs (points) | B33: =B26/Paramètres!$B$10 -> 0.13064312
A34: Gain d'un actif (€/mois) | B34: =($B$10/Paramètres!$B$7)*Paramètres!$B$9*(B33/100) -> 3.4557617
A35: Votre perte nette (€/mois) | B35: =B30*(1-$B$20) -> 13.703175
A36: Épargne mensuelle à cette pension (€) | B36: =$B$9*(1-$B$20)*$B$21 -> 495.405
A37: La perte en part de cette épargne | B37: =IF(B36>0,B35/B36,0) -> 0.02766055
A38: Effet sur le niveau de vie des actifs | B38: =Paramètres!$B$27*(Paramètres!$B$9*B33/100/Paramètres!$B$7) -> 0.0013839503
A39: Effet sur le niveau de vie des retraités | B39: =-Paramètres!$B$26*B26/Paramètres!$B$28 -> -0.0030492103
A40: Masse totale des pensions (Md€, contrôle) | B40: =$B$12*12*F97/1000000000 -> 402.23086
A49: Distribution des pensions totales brutes (Drees, EIR 2020, tableau 5), portée à 2026
A50: De (€ 2020) | B50: À (€ 2020) | C50: Part (%) | D50: De (€ 2026) | E50: À (€ 2026) | F50: Contribution à la moyenne | G50: Part au-dessus du seuil | H50: Masse au-dessus | I50: Masse au-delà du seuil
A51: 0 | B51: 100 | C51: 2.43 | D51: =A51*$B$13 -> 0 | E51: =B51*$B$13 -> 119 | F51: =C51/100*(D51+E51)/2 -> 1.44585 | G51: =IF(E51<=$B$4,0,(C51/100*(E51-MAX(D51,$B$4))/(E51-D51))) -> 0 | H51: =IF(E51<=$B$4,0,(C51/100*(E51-MAX(D51,$B$4))/(E51-D51))*(MAX(D51,$B$4)+E51)/2) -> 0 | I51: =IF(E51<=$B$4,0,(C51/100*(E51-MAX(D51,$B$4))/(E51-D51))*(MAX(D51,$B$4)+E51)/2-(C51/100*(E51-MAX(D51,$B$4))/(E51-D51))*$B$4) -> 0
...

Sheet Plafond
A1: Plafond des pensions : aucune pension totale au-delà d'un montant choisi
A4: Plafond de la pension totale brute (€/mois) | B4: 4000
A5: Votre pension brute mensuelle (€) | B5: 5000
A6: Part de l'économie versée aux actifs (salaires) | B6: 0
A8: Retraités, facteur 2020 → 2026 et tranche ouverte : repris de la feuille Gel.
A10: Résultats
A11: Part des retraités au-dessus du plafond | B11: =G77 -> 0.054403361
A12: Retraités concernés | B12: =G77*Gel!$B$12 -> 941178.15
A13: Économie annuelle (Md€) | B13: =Gel!$B$12*12*I77/1000000000 -> 15.904792
A14: En part de l'ensemble des pensions | B14: =B13/(Gel!$B$12*12*F77/1000000000) -> 0.03954145
A15: Gain net pour les finances publiques (Md€) | B15: =B13*Gel!$B$15 -> 12.405738
A16: Votre perte (€ brut par mois) | B16: =MAX(0,$B$5-$B$4) -> 1000
A17: Effet sur le niveau de vie des actifs | B17: =Paramètres!$B$27*(B13*$B$6/(Paramètres!$B$6*Paramètres!$B$7)) -> 0
A18: Effet sur le niveau de vie des retraités | B18: =-Paramètres!$B$26*B13/Paramètres!$B$28 -> -0.03093482
A29: Distribution des pensions (même source que la feuille Gel)
A30: De (€ 2020) | B30: À (€ 2020) | C30: Part (%) | D30: De (€ 2026) | E30: À (€ 2026) | F30: Contribution à la moyenne | G30: Part au-dessus du seuil | H30: Masse au-dessus | I30: Masse au-delà du seuil
A31: 0 | B31: 100 | C31: 2.43 | D31: =A31*Gel!$B$13 -> 0 | E31: =B31*Gel!$B$13 -> 119 | F31: =C31/100*(D31+E31)/2 -> 1.44585 | G31: =IF(E31<=$B$4,0,(C31/100*(E31-MAX(D31,$B$4))/(E31-D31))) -> 0 | H31: =IF(E31<=$B$4,0,(C31/100*(E31-MAX(D31,$B$4))/(E31-D31))*(MAX(D31,$B$4)+E31)/2) -> 0 | I31: =IF(E31<=$B$4,0,(C31/100*(E31-MAX(D31,$B$4))/(E31-D31))*(MAX(D31,$B$4)+E31)/2-(C31/100*(E31-MAX(D31,$B$4))/(E31-D31))*$B$4) -> 0
A32: 100 | B32: 200 | C32: 2.46 | D32: =A32*Gel!$B$13 -> 119 | E32: =B32*Gel!$B$13 -> 238 | F32: =C32/100*(D32+E32)/2 -> 4.3911 | G32: =IF(E32<=$B$4,0,(C32/100*(E32-MAX(D32,$B$4))/(E32-D32))) -> 0 | H32: =IF(E32<=$B$4,0,(C32/100*(E32-MAX(D32,$B$4))/(E32-D32))*(MAX(D32,$B$4)+E32)/2) -> 0 | I32: =IF(E32<=$B$4,0,(C32/100*(E32-MAX(D32,$B$4))/(E32-D32))*(MAX(D32,$B$4)+E32)/2-(C32/100*(E32-MAX(D32,$B$4))/(E32-D32))*$B$4) -> 0
A33: 200 | B33: 300 | C33: 2.35 | D33: =A33*Gel!$B$13 -> 238 | E33: =B33*Gel!$B$13 -> 357 | F33: =C33/100*(D33+E33)/2 -> 6.99125 | G33: =IF(E33<=$B$4,0,(C33/100*(E33-MAX(D33,$B$4))/(E33-D33))) -> 0 | H33: =IF(E33<=$B$4,0,(C33/100*(E33-MAX(D33,$B$4))/(E33-D33))*(MAX(D33,$B$4)+E33)/2) -> 0 | I33: =IF(E33<=$B$4,0,(C33/100*(E33-MAX(D33,$B$4))/(E33-D33))*(MAX(D33,$B$4)+E33)/2-(C33/100*(E33-MAX(D33,$B$4))/(E33-D33))*$B$4) -> 0
A34: 300 | B34: 400 | C34: 2.17 | D34: =A34*Gel!$B$13 -> 357 | E34: =B34*Gel!$B$13 -> 476 | F34: =C34/100*(D34+E34)/2 -> 9.03805 | G34: =IF(E34<=$B$4,0,(C34/100*(E34-MAX(D34,$B$4))/(E34-D34))) -> 0 | H34: =IF(E34<=$B$4,0,(C34/100*(E34-MAX(D34,$B$4))/(E34-D34))*(MAX(D34,$B$4)+E34)/2) -> 0 | I34: =IF(E34<=$B$4,0,(C34/100*(E34-MAX(D34,$B$4))/(E34-D34))*(MAX(D34,$B$4)+E34)/2-(C34/100*(E34-MAX(D34,$B$4))/(E34-D34))*$B$4) -> 0
A35: 400 | B35: 500 | C35: 2 | D35: =A35*Gel!$B$13 -> 476 | E35: =B35*Gel!$B$13 -> 595 | F35: =C35/100*(D35+E35)/2 -> 10.71 | G35: =IF(E35<=$B$4,0,(C35/100*(E35-MAX(D35,$B$4))/(E35-D35))) -> 0 | H35: =IF(E35<=$B$4,0,(C35/100*(E35-MAX(D35,$B$4))/(E35-D35))*(MAX(D35,$B$4)+E35)/2) -> 0 | I35: =IF(E35<=$B$4,0,(C35/100*(E35-MAX(D35,$B$4))/(E35-D35))*(MAX(D35,$B$4)+E35)/2-(C35/100*(E35-MAX(D35,$B$4))/(E35-D35))*$B$4) -> 0
A36: 500 | B36: 600 | C36: 2.06 | D36: =A36*Gel!$B$13 -> 595 | E36: =B36*Gel!$B$13 -> 714 | F36: =C36/100*(D36+E36)/2 -> 13.4827 | G36: =IF(E36<=$B$4,0,(C36/100*(E36-MAX(D36,$B$4))/(E36-D36))) -> 0 | H36: =IF(E36<=$B$4,0,(C36/100*(E36-MAX(D36,$B$4))/(E36-D36))*(MAX(D36,$B$4)+E36)/2) -> 0 | I36: =IF(E36<=$B$4,0,(C36/100*(E36-MAX(D36,$B$4))/(E36-D36))*(MAX(D36,$B$4)+E36)/2-(C36/100*(E36-MAX(D36,$B$4))/(E36-D36))*$B$4) -> 0
A37: 600 | B37: 700 | C37: 2.28 | D37: =A37*Gel!$B$13 -> 714 | E37: =B37*Gel!$B$13 -> 833 | F37: =C37/100*(D37+E37)/2 -> 17.6358 | G37: =IF(E37<=$B$4,0,(C37/100*(E37-MAX(D37,$B$4))/(E37-D37))) -> 0 | H37: =IF(E37<=$B$4,0,(C37/100*(E37-MAX(D37,$B$4))/(E37-D37))*(MAX(D37,$B$4)+E37)/2) -> 0 | I37: =IF(E37<=$B$4,0,(C37/100*(E37-MAX(D37,$B$4))/(E37-D37))*(MAX(D37,$B$4)+E37)/2-(C37/100*(E37-MAX(D37,$B$4))/(E37-D37))*$B$4) -> 0
A38: 700 | B38: 800 | C38: 2.94 | D38: =A38*Gel!$B$13 -> 833 | E38: =B38*Gel!$B$13 -> 952 | F38: =C38/100*(D38+E38)/2 -> 26.2395 | G38: =IF(E38<=$B$4,0,(C38/100*(E38-MAX(D38,$B$4))/(E38-D38))) -> 0 | H38: =IF(E38<=$B$4,0,(C38/100*(E38-MAX(D38,$B$4))/(E38-D38))*(MAX(D38,$B$4)+E38)/2) -> 0 | I38: =IF(E38<=$B$4,0,(C38/100*(E38-MAX(D38,$B$4))/(E38-D38))*(MAX(D38,$B$4)+E38)/2-(C38/100*(E38-MAX(D38,$B$4))/(E38-D38))*$B$4) -> 0
A39: 800 | B39: 900 | C39: 4.36 | D39: =A39*Gel!$B$13 -> 952 | E39: =B39*Gel!$B$13 -> 1071 | F39: =C39/100*(D39+E39)/2 -> 44.1014 | G39: =IF(E39<=$B$4,0,(C39/100*(E39-MAX(D39,$B$4))/(E39-D39))) -> 0 | H39: =IF(E39<=$B$4,0,(C39/100*(E39-MAX(D39,$B$4))/(E39-D39))*(MAX(D39,$B$4)+E39)/2) -> 0 | I39: =IF(E39<=$B$4,0,(C39/100*(E39-MAX(D39,$B$4))/(E39-D39))*(MAX(D39,$B$4)+E39)/2-(C39/100*(E39-MAX(D39,$B$4))/(E39-D39))*$B$4) -> 0
A40: 900 | B40: 1000 | C40: 4.44 | D40: =A40*Gel!$B$13 -> 1071 | E40: =B40*Gel!$B$13 -> 1190 | F40: =C40/100*(D40+E40)/2 -> 50.1942 | G40: =IF(E40<=$B$4,0,(C40/100*(E40-MAX(D40,$B$4))/(E40-D40))) -> 0 | H40: =IF(E40<=$B$4,0,(C40/100*(E40-MAX(D40,$B$4))/(E40-D40))*(MAX(D40,$B$4)+E40)/2) -> 0 | I40: =IF(E40<=$B$4,0,(C40/100*(E40-MAX(D40,$B$4))/(E40-D40))*(MAX(D40,$B$4)+E40)/2-(C40/100*(E40-MAX(D40,$B$4))/(E40-D40))*$B$4) -> 0
A41: 1000 | B41: 1100 | C41: 4.2 | D41: =A41*Gel!$B$13 -> 1190 | E41: =B41*Gel!$B$13 -> 1309 | F41: =C41/100*(D41+E41)/2 -> 52.479 | G41: =IF(E41<=$B$4,0,(C41/100*(E41-MAX(D41,$B$4))/(E41-D41))) -> 0 | H41: =IF(E41<=$B$4,0,(C41/100*(E41-MAX(D41,$B$4))/(E41-D41))*(MAX(D41,$B$4)+E41)/2) -> 0 | I41: =IF(E41<=$B$4,0,(C41/100*(E41-MAX(D41,$B$4))/(E41-D41))*(MAX(D41,$B$4)+E41)/2-(C41/100*(E41-MAX(D41,$B$4))/(E41-D41))*$B$4) -> 0
A42: 1100 | B42: 1200 | C42: 4.4 | D42: =A42*Gel!$B$13 -> 1309 | E42: =B42*Gel!$B$13 -> 1428 | F42: =C42/100*(D42+E42)/2 -> 60.214 | G42: =IF(E42<=$B$4,0,(C42/100*(E42-MAX(D42,$B$4))/(E42-D42))) -> 0 | H42: =IF(E42<=$B$4,0,(C42/100*(E42-MAX(D42,$B$4))/(E42-D42))*(MAX(D42,$B$4)+E42)/2) -> 0 | I42: =IF(E42<=$B$4,0,(C42/100*(E42-MAX(D42,$B$4))/(E42-D42))*(MAX(D42,$B$4)+E42)/2-(C42/100*(E42-MAX(D42,$B$4))/(E42-D42))*$B$4) -> 0
... A75: 4400 | B75: 4500 | C75: 0.18 | D75: =A75*Gel!$B$13 -> 5236 | E75: =B75*Gel!$B$13 -> 5355 | F75: =C75/100*(D75+E75)/2 -> 9.5319 | G75: =IF(E75<=$B$4,0,(C75/100*(E75-MAX(D75,$B$4))/(E75-D75))) -> 0.0018 | H75: =IF(E75<=$B$4,0,(C75/100*(E75-MAX(D75,$B$4))/(E75-D75))*(MAX(D75,$B$4)+E75)/2) -> 9.5319 | I75: =IF(E75<=$B$4,0,(C75/100*(E75-MAX(D75,$B$4))/(E75-D75))*(MAX(D75,$B$4)+E75)/2-(C75/100*(E75-MAX(D75,$B$4))/(E75-D75))*$B$4) -> 2.3319
A76: 4500 | B76: et plus | C76: 1.82 | D76: =A76*Gel!$B$13 -> 5355 | E76: =Gel!$B$14*Gel!$B$13 -> 7140 | F76: =C76/100*E76 -> 129.948 | G76: =IF(E76>$B$4,C76/100,0) -> 0.0182 | H76: =IF(E76>$B$4,C76/100*E76,0) -> 129.948 | I76: =IF(E76>$B$4,C76/100*(E76-$B$4),0) -> 57.148
A77: Total (par retraité, €/mois) | F77: =SUM(F31:F76) -> 1937.5283 | G77: =SUM(G31:G76) -> 0.054403361 | H77: =SUM(H31:H76) -> 294.22612 | I77: =SUM(I31:I76) -> 76.612677

Sheet Niveaux de vie
A1: Retraités et actifs : niveau de vie médian, et effet des réformes choisies
A2: Effets cumulés multiplicativement ; hypothèse : l'effet « actifs » s'applique aux personnes en emploi, l'effet « retraités » aux retraités.
A4: Réforme | B4: Inclure | C4: Effet actifs | D4: Effet retraités | E4: Facteur actifs | F4: Facteur retraités
A5: TVA sociale | B5: Oui | C5: ='TVA sociale'!B17 -> 0.0067453564 | D5: ='TVA sociale'!B18 -> -0.0064963504 | E5: =IF(B5="Oui",1+C5,1) -> 1.0067454 | F5: =IF(B5="Oui",1+D5,1) -> 0.99350365
A6: CSG des retraités | B6: Oui | C6: ='CSG retraités'!B19 -> 0.0017876304 | D6: ='CSG retraités'!B20 -> -0.003938625 | E6: =IF(B6="Oui",1+C6,1) -> 1.0017876 | F6: =IF(B6="Oui",1+D6,1) -> 0.99606138
A7: Retraites sans impôts | B7: Oui | C7: ='Sans impôts'!B30 -> -0.040852156 | D7: ='Sans impôts'!B31 -> -0.0773946 | E7: =IF(B7="Oui",1+C7,1) -> 0.95914784 | F7: =IF(B7="Oui",1+D7,1) -> 0.9226054
A8: Gel des hautes pensions | B8: Oui | C8: =Gel!B38 -> 0.0013839503 | D8: =Gel!B39 -> -0.0030492103 | E8: =IF(B8="Oui",1+C8,1) -> 1.001384 | F8: =IF(B8="Oui",1+D8,1) -> 0.99695079
A9: Plafond des pensions | B9: Oui | C9: =Plafond!B17 -> 0 | D9: =Plafond!B18 -> -0.03093482 | E9: =IF(B9="Oui",1+C9,1) -> 1 | F9: =IF(B9="Oui",1+D9,1) -> 0.96906518
A11: Effet cumulé, actifs | B11: =PRODUCT(E5:E9)-1 -> -0.031317439
A12: Effet cumulé, retraités | B12: =PRODUCT(F5:F9)-1 -> -0.11793971
A14: Niveaux de vie médians 2024 (€ 2024 par an)
B15: Avant | C15: Après | D15: Par mois avant | E15: Par mois après
A16: Personnes en emploi | B16: 29860 | C16: =B16*(1+B11) -> 28924.861 | D16: =B16/12 -> 2488.3333 | E16: =C16/12 -> 2410.4051
A17: Retraités | B17: 26830 | C17: =B17*(1+B12) -> 23665.678 | D17: =B17/12 -> 2235.8333 | E17: =C17/12 -> 1972.1398
A18: Retraités / en emploi | B18: =B17/B16 -> 0.89852646 | C18: =C17/C16 -> 0.81817774
A20: Série 1996-2024 (Insee, ERFS, € constants 2024, médianes annuelles)
A21: Année | B21: Ensemble | C21: Retraités | D21: En emploi | E21: Retraités / en emploi
A22: 1996 | B22: 20670 | C22: 21280 | D22: 23080 | E22: =C22/D22 -> 0.9220104
A23: 1997 | B23: 20700 | C23: 21010 | D23: 23300 | E23: =C23/D23 -> 0.90171674
A24: 1998 | B24: 21130 | C24: 21350 | D24: 23800 | E24: =C24/D24 -> 0.89705882
A25: 1999 | B25: 21440 | C25: 21850 | D25: 23930 | E25: =C25/D25 -> 0.91307982
A26: 2000 | B26: 21830 | C26: 22030 | D26: 24290 | E26: =C26/D26 -> 0.9069576
A27: 2001 | B27: 22370 | C27: 22420 | D27: 24920 | E27: =C27/D27 -> 0.89967897
A28: 2002 | B28: 22960 | C28: 22690 | D28: 25620 | E28: =C28/D28 -> 0.88563622
A29: 2003 | B29: 22900 | C29: 22610 | D29: 25500 | E29: =C29/D29 -> 0.88666667
A30: 2004 | B30: 22780 | C30: 22580 | D30: 25430 | E30: =C30/D30 -> 0.88792764
A31: 2005 | B31: 23190 | C31: 22830 | D31: 25810 | E31: =C31/D31 -> 0.88454088
A32: 2006 | B32: 23520 | C32: 23670 | D32: 25980 | E32: =C32/D32 -> 0.91108545
A33: 2007 | B33: 24010 | C33: 23970 | D33: 26680 | E33: =C33/D33 -> 0.89842579
... A50: 2024 | B50: 26740 | C50: 26830 | D50: 29860 | E50: =C50/D50 -> 0.89852646

Sheet Rendement
A1: Pensions reçues pour 100 000 € cotisés, selon la génération
A2: Modèle du site calé sur le TRI du COR (cas type non-cadre, carrière complète), trimestre par trimestre. Valeurs actualisées en plus de l'évolution des salaires.
A4: Génération (année de naissance) | B4: 1960
A5: Taux d'actualisation (en plus des salaires) | B5: 0
A6: Décrochage annuel des pensions par rapport aux salaires | B6: 0.01
A7: Compter aussi les impôts affectés aux retraites | B7: Non
I9: Part des ressources hors cotisations (COR) | L9: Part payée par les retraités
A10: Génération | B10: TRI (COR) | C10: Durée de retraite | D10: Espérance de vie à 60 ans | E10: Durée de carrière | I10: Année | J10: Part | L10: Année | M10: Part
A11: 1940 | B11: 0.01985 | C11: 24.71 | D11: 25.52 | E11: 35.3 | I11: 1987 | J11: 0.121 | L11: 1993 | M11: 0
A12: 1945 | B12: 0.01887 | C12: 25.01 | D12: 25.79 | E12: 36.27 | I12: 2004 | J12: 0.1797 | L12: 2018 | M12: 0.05
A13: 1950 | B13: 0.01768 | C13: 25.51 | D13: 25.99 | E13: 38.02 | I13: 2005 | J13: 0.179
A14: 1955 | B14: 0.01243 | C14: 24.18 | D14: 26.1 | E14: 39.46 | I14: 2006 | J14: 0.1795
A15: 1960 | B15: 0.01212 | C15: 24.23 | D15: 26.67 | E15: 39.33 | I15: 2007 | J15: 0.1771
A16: 1965 | B16: 0.01105 | C16: 23.77 | D16: 27.25 | E16: 39.13 | I16: 2008 | J16: 0.1906
A17: 1970 | B17: 0.00882 | C17: 23.6 | D17: 27.78 | E17: 39.05 | I17: 2009 | J17: 0.1811
A18: 1975 | B18: 0.00776 | C18: 23.81 | D18: 28.3 | E18: 38.34 | I18: 2010 | J18: 0.1775
A19: 1980 | B19: 0.00796 | C19: 24.33 | D19: 28.8 | E19: 38.35 | I19: 2011 | J19: 0.1934
A20: 1985 | B20: 0.00786 | C20: 24.73 | D20: 29.29 | E20: 38.04 | I20: 2012 | J20: 0.1974
A21: 1990 | B21: 0.00795 | C21: 25.16 | D21: 29.74 | E21: 37.85 | I21: 2013 | J21: 0.205
A22: 1995 | B22: 0.00824 | C22: 25.58 | D22: 30.17 | E22: 37.87 | I22: 2014 | J22: 0.208
A23: 2000 | B23: 0.00827 | C23: 26.02 | D23: 30.58 | E23: 37.91 | I23: 2015 | J23: 0.2089
I24: 2016 | J24: 0.2081
I25: 2017 | J25: 0.2052
I26: 2018 | J26: 0.2026
I27: 2019 | J27: 0.2005
I28: 2020 | J28: 0.2158
A29: Calendrier et résultat | I29: 2021 | J29: 0.2079
A30: TRI de la génération (COR) | B30: =INDEX(B$11:B$23,MATCH($B$4,$A$11:$A$23,0)) -> 0.01212 | I30: 2022 | J30: 0.2101
A31: Âge de départ | B31: =60+INDEX(D$11:D$23,MATCH($B$4,$A$11:$A$23,0))-INDEX(C$11:C$23,MATCH($B$4,$A$11:$A$23,0)) -> 62.44 | I31: 2023 | J31: 0.2089
A32: Âge de début de carrière | B32: =B31-INDEX(E$11:E$23,MATCH($B$4,$A$11:$A$23,0)) -> 23.11 | I32: 2024 | J32: 0.2089
A33: Âge de fin de retraite | B33: =B31+INDEX(C$11:C$23,MATCH($B$4,$A$11:$A$23,0)) -> 86.67 | I33: 2025 | J33: 0.2104
A34: Calage : pension / cotisation (au TRI du COR) | B34: =SUM(D60:D259)/SUM(I60:I259) -> 2.6757221
A35: Pensions reçues pour 100 000 € cotisés (valeur actualisée) | B35: =100000*B34*SUM(J60:J259)/SUM(E60:E259) -> 146711.47
A57: Grille trimestrielle (pas de 0,25 an ; une ligne compte si l'âge est dans la période)
A59: Cotisation : âge | B59: Compte | C59: Mult. impôts | D59: Poids au TRI | E59: Poids actualisé | G59: Pension : âge | H59: Compte | I59: Poids au TRI | J59: Poids actualisé | L59: Mult. impôts
A60: =$B$32+0.125+0*0.25 -> 23.235 | B60: =IF(A60<$B$31,1,0) -> 1 | C60: =IF($B$7="Oui",1+((IF(($B$4+A60)<=$I$11,$J$11,IF(($B$4+A60)>=$I$33,$J$33,INDEX($J$11:$J$33,MATCH(($B$4+A60),$I$11:$I$33,1))+(INDEX($J$11:$J$33,MATCH(($B$4+A60),$I$11:$I$33,1)+1)-INDEX($J$11:$J$33,MATCH(($B$4+A60),$I$11:$I$33,1)))*(($B$4+A60)-INDEX($I$11:$I$33,MATCH(($B$4+A60),$I$11:$I$33,1)))/(INDEX($I$11:$I$33,MATCH(($B$4+A60),$I$11:$I$33,1)+1)-INDEX($I$11:$I$33,MATCH(($B$4+A60),$I$11:$I$33,1))))))-(IF(($B$4+A60)<=$L$11,$M$11,IF(($B$4+A60)>=$L$12,$M$12,INDEX($M$11:$M$12,MATCH(($B$4+A60),$L$11:$L$12,1))+(INDEX($M$11:$M$12,MATCH(($B$4+A60),$L$11:$L$12,1)+1)-INDEX($M$11:$M$12,MATCH(($B$4+A60),$L$11:$L$12,1)))*(($B$4+A60)-INDEX($L$11:$L$12,MATCH(($B$4+A60),$L$11:$L$12,1)))/(INDEX($L$11:$L$12,MATCH(($B$4+A60),$L$11:$L$12,1)+1)-INDEX($L$11:$L$12,MATCH(($B$4+A60),$L$11:$L$12,1)))))))/(1-(IF(($B$4+A60)<=$I$11,$J$11,IF(($B$4+A60)>=$I$33,$J$33,INDEX($J$11:$J$33,MATCH(($B$4+A60),$I$11:$I$33,1))+(INDEX($J$11:$J$33,MATCH(($B$4+A60),$I$11:$I$33,1)+1)-INDEX($J$11:$J$33,MATCH(($B$4+A60),$I$11:$I$33,1)))*(($B$4+A60)-INDEX($I$11:$I$33,MATCH(($B$4+A60),$I$11:$I$33,1)))/(INDEX($I$11:$I$33,MATCH(($B$4+A60),$I$11:$I$33,1)+1)-INDEX($I$11:$I$33,MATCH(($B$4+A60),$I$11:$I$33,1))))))),1) -> 1 | D60: =B60*(1+$B$30)^(-A60) -> 0.75584774 | E60: =B60*C60*(1+$B$5)^(-A60) -> 1 | G60: =$B$31+0.125+0*0.25 -> 62.565 | H60: =IF(G60<$B$33,1,0) -> 1 | I60: =H60*(1-$B$6)^(G60-$B$31)*(1+$B$30)^(-G60) -> 0.47001735 | J60: =H60*(1-$B$6)^(G60-$B$31)*L60*(1+$B$5)^(-G60) -> 0.9987445 | L60: =IF($B$7="Oui",1-(IF(($B$4+G60)<=$L$11,$M$11,IF(($B$4+G60)>=$L$12,$M$12,INDEX($M$11:$M$12,MATCH(($B$4+G60),$L$11:$L$12,1))+(INDEX($M$11:$M$12,MATCH(($B$4+G60),$L$11:$L$12,1)+1)-INDEX($M$11:$M$12,MATCH(($B$4+G60),$L$11:$L$12,1)))*(($B$4+G60)-INDEX($L$11:$L$12,MATCH(($B$4+G60),$L$11:$L$12,1)))/(INDEX($L$11:$L$12,MATCH(($B$4+G60),$L$11:$L$12,1)+1)-INDEX($L$11:$L$12,MATCH(($B$4+G60),$L$11:$L$12,1)))))),1) -> 1
A61: =$B$32+0.125+1*0.25 -> 23.485 | B61: =IF(A61<$B$31,1,0) -> 1 | C61: =IF($B$7="Oui",1+((IF(($B$4+A61)<=$I$11,$J$11,IF(($B$4+A61)>=$I$33,$J$33,INDEX($J$11:$J$33,MATCH(($B$4+A61),$I$11:$I$33,1))+(INDEX($J$11:$J$33,MATCH(($B$4+A61),$I$11:$I$33,1)+1)-INDEX($J$11:$J$33,MATCH(($B$4+A61),$I$11:$I$33,1)))*(($B$4+A61)-INDEX($I$11:$I$33,MATCH(($B$4+A61),$I$11:$I$33,1)))/(INDEX($I$11:$I$33,MATCH(($B$4+A61),$I$11:$I$33,1)+1)-INDEX($I$11:$I$33,MATCH(($B$4+A61),$I$11:$I$33,1))))))-(IF(($B$4+A61)<=$L$11,$M$11,IF(($B$4+A61)>=$L$12,$M$12,INDEX($M$11:$M$12,MATCH(($B$4+A61),$L$11:$L$12,1))+(INDEX($M$11:$M$12,MATCH(($B$4+A61),$L$11:$L$12,1)+1)-INDEX($M$11:$M$12,MATCH(($B$4+A61),$L$11:$L$12,1)))*(($B$4+A61)-INDEX($L$11:$L$12,MATCH(($B$4+A61),$L$11:$L$12,1)))/(INDEX($L$11:$L$12,MATCH(($B$4+A61),$L$11:$L$12,1)+1)-INDEX($L$11:$L$12,MATCH(($B$4+A61),$L$11:$L$12,1)))))))/(1-(IF(($B$4+A61)<=$I$11,$J$11,IF(($B$4+A61)>=$I$33,$J$33,INDEX($J$11:$J$33,MATCH(($B$4+A61),$I$11:$I$33,1))+(INDEX($J$11:$J$33,MATCH(($B$4+A61),$I$11:$I$33,1)+1)-INDEX($J$11:$J$33,MATCH(($B$4+A61),$I$11:$I$33,1)))*(($B$4+A61)-INDEX($I$11:$I$33,MATCH(($B$4+A61),$I$11:$I$33,1)))/(INDEX($I$11:$I$33,MATCH(($B$4+A61),$I$11:$I$33,1)+1)-INDEX($I$11:$I$33,MATCH(($B$4+A61),$I$11:$I$33,1))))))),1) -> 1 | D61: =B61*(1+$B$30)^(-A61) -> 0.75357472 | E61: =B61*C61*(1+$B$5)^(-A61) -> 1 | G61: =$B$31+0.125+1*0.25 -> 62.815 | H61: =IF(G61<$B$33,1,0) -> 1 | I61: =H61*(1-$B$6)^(G61-$B$31)*(1+$B$30)^(-G61) -> 0.46742796 | J61: =H61*(1-$B$6)^(G61-$B$31)*L61*(1+$B$5)^(-G61) -> 0.99623822 | L61: =IF($B$7="Oui",1-(IF(($B$4+G61)<=$L$11,$M$11,IF(($B$4+G61)>=$L$12,$M$12,INDEX($M$11:$M$12,MATCH(($B$4+G61),$L$11:$L$12,1))+(INDEX($M$11:$M$12,MATCH(($B$4+G61),$L$11:$L$12,1)+1)-INDEX($M$11:$M$12,MATCH(($B$4+G61),$L$11:$L$12,1)))*(($B$4+G61)-INDEX($L$11:$L$12,MATCH(($B$4+G61),$L$11:$L$12,1)))/(INDEX($L$11:$L$12,MATCH(($B$4+G61),$L$11:$L$12,1)+1)-INDEX($L$11:$L$12,MATCH(($B$4+G61),$L$11:$L$12,1)))))),1) -> 1
A62: =$B$32+0.125+2*0.25 -> 23.735 | B62: =IF(A62<$B$31,1,0) -> 1 | C62: =IF($B$7="Oui",1+((IF(($B$4+A62)<=$I$11,$J$11,IF(($B$4+A62)>=$I$33,$J$33,INDEX($J$11:$J$33,MATCH(($B$4+A62),$I$11:$I$33,1))+(INDEX($J$11:$J$33,MATCH(($B$4+A62),$I$11:$I$33,1)+1)-INDEX($J$11:$J$33,MATCH(($B$4+A62),$I$11:$I$33,1)))*(($B$4+A62)-INDEX($I$11:$I$33,MATCH(($B$4+A62),$I$11:$I$33,1)))/(INDEX($I$11:$I$33,MATCH(($B$4+A62),$I$11:$I$33,1)+1)-INDEX($I$11:$I$33,MATCH(($B$4+A62),$I$11:$I$33,1))))))-(IF(($B$4+A62)<=$L$11,$M$11,IF(($B$4+A62)>=$L$12,$M$12,INDEX($M$11:$M$12,MATCH(($B$4+A62),$L$11:$L$12,1))+(INDEX($M$11:$M$12,MATCH(($B$4+A62),$L$11:$L$12,1)+1)-INDEX($M$11:$M$12,MATCH(($B$4+A62),$L$11:$L$12,1)))*(($B$4+A62)-INDEX($L$11:$L$12,MATCH(($B$4+A62),$L$11:$L$12,1)))/(INDEX($L$11:$L$12,MATCH(($B$4+A62),$L$11:$L$12,1)+1)-INDEX($L$11:$L$12,MATCH(($B$4+A62),$L$11:$L$12,1)))))))/(1-(IF(($B$4+A62)<=$I$11,$J$11,IF(($B$4+A62)>=$I$33,$J$33,INDEX($J$11:$J$33,MATCH(($B$4+A62),$I$11:$I$33,1))+(INDEX($J$11:$J$33,MATCH(($B$4+A62),$I$11:$I$33,1)+1)-INDEX($J$11:$J$33,MATCH(($B$4+A62),$I$11:$I$33,1)))*(($B$4+A62)-INDEX($I$11:$I$33,MATCH(($B$4+A62),$I$11:$I$33,1)))/(INDEX($I$11:$I$33,MATCH(($B$4+A62),$I$11:$I$33,1)+1)-INDEX($I$11:$I$33,MATCH(($B$4+A62),$I$11:$I$33,1))))))),1) -> 1 | D62: =B62*(1+$B$30)^(-A62) -> 0.75130853 | E62: =B62*C62*(1+$B$5)^(-A62) -> 1 | G62: =$B$31+0.125+2*0.25 -> 63.065 | H62: =IF(G62<$B$33,1,0) -> 1 | I62: =H62*(1-$B$6)^(G62-$B$31)*(1+$B$30)^(-G62) -> 0.46485284 | J62: =H62*(1-$B$6)^(G62-$B$31)*L62*(1+$B$5)^(-G62) -> 0.99373823 | L62: =IF($B$7="Oui",1-(IF(($B$4+G62)<=$L$11,$M$11,IF(($B$4+G62)>=$L$12,$M$12,INDEX($M$11:$M$12,MATCH(($B$4+G62),$L$11:$L$12,1))+(INDEX($M$11:$M$12,MATCH(($B$4+G62),$L$11:$L$12,1)+1)-INDEX($M$11:$M$12,MATCH(($B$4+G62),$L$11:$L$12,1)))*(($B$4+G62)-INDEX($L$11:$L$12,MATCH(($B$4+G62),$L$11:$L$12,1)))/(INDEX($L$11:$L$12,MATCH(($B$4+G62),$L$11:$L$12,1)+1)-INDEX($L$11:$L$12,MATCH(($B$4+G62),$L$11:$L$12,1)))))),1) -> 1
A63: =$B$32+0.125+3*0.25 -> 23.985 | B63: =IF(A63<$B$31,1,0) -> 1 | C63: =IF($B$7="Oui",1+((IF(($B$4+A63)<=$I$11,$J$11,IF(($B$4+A63)>=$I$33,$J$33,INDEX($J$11:$J$33,MATCH(($B$4+A63),$I$11:$I$33,1))+(INDEX($J$11:$J$33,MATCH(($B$4+A63),$I$11:$I$33,1)+1)-INDEX($J$11:$J$33,MATCH(($B$4+A63),$I$11:$I$33,1)))*(($B$4+A63)-INDEX($I$11:$I$33,MATCH(($B$4+A63),$I$11:$I$33,1)))/(INDEX($I$11:$I$33,MATCH(($B$4+A63),$I$11:$I$33,1)+1)-INDEX($I$11:$I$33,MATCH(($B$4+A63),$I$11:$I$33,1))))))-(IF(($B$4+A63)<=$L$11,$M$11,IF(($B$4+A63)>=$L$12,$M$12,INDEX($M$11:$M$12,MATCH(($B$4+A63),$L$11:$L$12,1))+(INDEX($M$11:$M$12,MATCH(($B$4+A63),$L$11:$L$12,1)+1)-INDEX($M$11:$M$12,MATCH(($B$4+A63),$L$11:$L$12,1)))*(($B$4+A63)-INDEX($L$11:$L$12,MATCH(($B$4+A63),$L$11:$L$12,1)))/(INDEX($L$11:$L$12,MATCH(($B$4+A63),$L$11:$L$12,1)+1)-INDEX($L$11:$L$12,MATCH(($B$4+A63),$L$11:$L$12,1)))))))/(1-(IF(($B$4+A63)<=$I$11,$J$11,IF(($B$4+A63)>=$I$33,$J$33,INDEX($J$11:$J$33,MATCH(($B$4+A63),$I$11:$I$33,1))+(INDEX($J$11:$J$33,MATCH(($B$4+A63),$I$11:$I$33,1)+1)-INDEX($J$11:$J$33,MATCH(($B$4+A63),$I$11:$I$33,1)))*(($B$4+A63)-INDEX($I$11:$I$33,MATCH(($B$4+A63),$I$11:$I$33,1)))/(INDEX($I$11:$I$33,MATCH(($B$4+A63),$I$11:$I$33,1)+1)-INDEX($I$11:$I$33,MATCH(($B$4+A63),$I$11:$I$33,1))))))),1) -> 1 | D63: =B63*(1+$B$30)^(-A63) -> 0.74904915 | E63: =B63*C63*(1+$B$5)^(-A63) -> 1 | G63: =$B$31+0.125+3*0.25 -> 63.315 | H63: =IF(G63<$B$33,1,0) -> 1 | I63: =H63*(1-$B$6)^(G63-$B$31)*(1+$B$30)^(-G63) -> 0.4622919 | J63: =H63*(1-$B$6)^(G63-$B$31)*L63*(1+$B$5)^(-G63) -> 0.99124451 | L63: =IF($B$7="Oui",1-(IF(($B$4+G63)<=$L$11,$M$11,IF(($B$4+G63)>=$L$12,$M$12,INDEX($M$11:$M$12,MATCH(($B$4+G63),$L$11:$L$12,1))+(INDEX($M$11:$M$12,MATCH(($B$4+G63),$L$11:$L$12,1)+1)-INDEX($M$11:$M$12,MATCH(($B$4+G63),$L$11:$L$12,1)))*(($B$4+G63)-INDEX($L$11:$L$12,MATCH(($B$4+G63),$L$11:$L$12,1)))/(INDEX($L$11:$L$12,MATCH(($B$4+G63),$L$11:$L$12,1)+1)-INDEX($L$11:$L$12,MATCH(($B$4+G63),$L$11:$L$12,1)))))),1) -> 1
A64: =$B$32+0.125+4*0.25 -> 24.235 | B64: =IF(A64<$B$31,1,0) -> 1 | C64: =IF($B$7="Oui",1+((IF(($B$4+A64)<=$I$11,$J$11,IF(($B$4+A64)>=$I$33,$J$33,INDEX($J$11:$J$33,MATCH(($B$4+A64),$I$11:$I$33,1))+(INDEX($J$11:$J$33,MATCH(($B$4+A64),$I$11:$I$33,1)+1)-INDEX($J$11:$J$33,MATCH(($B$4+A64),$I$11:$I$33,1)))*(($B$4+A64)-INDEX($I$11:$I$33,MATCH(($B$4+A64),$I$11:$I$33,1)))/(INDEX($I$11:$I$33,MATCH(($B$4+A64),$I$11:$I$33,1)+1)-INDEX($I$11:$I$33,MATCH(($B$4+A64),$I$11:$I$33,1))))))-(IF(($B$4+A64)<=$L$11,$M$11,IF(($B$4+A64)>=$L$12,$M$12,INDEX($M$11:$M$12,MATCH(($B$4+A64),$L$11:$L$12,1))+(INDEX($M$11:$M$12,MATCH(($B$4+A64),$L$11:$L$12,1)+1)-INDEX($M$11:$M$12,MATCH(($B$4+A64),$L$11:$L$12,1)))*(($B$4+A64)-INDEX($L$11:$L$12,MATCH(($B$4+A64),$L$11:$L$12,1)))/(INDEX($L$11:$L$12,MATCH(($B$4+A64),$L$11:$L$12,1)+1)-INDEX($L$11:$L$12,MATCH(($B$4+A64),$L$11:$L$12,1)))))))/(1-(IF(($B$4+A64)<=$I$11,$J$11,IF(($B$4+A64)>=$I$33,$J$33,INDEX($J$11:$J$33,MATCH(($B$4+A64),$I$11:$I$33,1))+(INDEX($J$11:$J$33,MATCH(($B$4+A64),$I$11:$I$33,1)+1)-INDEX($J$11:$J$33,MATCH(($B$4+A64),$I$11:$I$33,1)))*(($B$4+A64)-INDEX($I$11:$I$33,MATCH(($B$4+A64),$I$11:$I$33,1)))/(INDEX($I$11:$I$33,MATCH(($B$4+A64),$I$11:$I$33,1)+1)-INDEX($I$11:$I$33,MATCH(($B$4+A64),$I$11:$I$33,1))))))),1) -> 1 | D64: =B64*(1+$B$30)^(-A64) -> 0.74679657 | E64: =B64*C64*(1+$B$5)^(-A64) -> 1 | G64: =$B$31+0.125+4*0.25 -> 63.565 | H64: =IF(G64<$B$33,1,0) -> 1 | I64: =H64*(1-$B$6)^(G64-$B$31)*(1+$B$30)^(-G64) -> 0.45974507 | J64: =H64*(1-$B$6)^(G64-$B$31)*L64*(1+$B$5)^(-G64) -> 0.98875705 | L64: =IF($B$7="Oui",1-(IF(($B$4+G64)<=$L$11,$M$11,IF(($B$4+G64)>=$L$12,$M$12,INDEX($M$11:$M$12,MATCH(($B$4+G64),$L$11:$L$12,1))+(INDEX($M$11:$M$12,MATCH(($B$4+G64),$L$11:$L$12,1)+1)-INDEX($M$11:$M$12,MATCH(($B$4+G64),$L$11:$L$12,1)))*(($B$4+G64)-INDEX($L$11:$L$12,MATCH(($B$4+G64),$L$11:$L$12,1)))/(INDEX($L$11:$L$12,MATCH(($B$4+G64),$L$11:$L$12,1)+1)-INDEX($L$11:$L$12,MATCH(($B$4+G64),$L$11:$L$12,1)))))),1) -> 1
...

Sheet Sources
A1: Sources
A3: Donnée | B3: Source | C3: Lien
A4: Financement et dépenses des retraites | B4: COR, rapport annuel juin 2026, tableau 2.2 | C4: https://www.cor-retraites.fr/sites/default/files/2026-06/RA_2026_def.pdf
A5: CSG, barème des retraités | B5: Code de la sécurité sociale, art. L136-8 ; seuils 2025 : service-public.gouv.fr | C5: https://www.service-public.gouv.fr/particuliers/vosdroits/F2971
A6: Recettes de CSG d'activité | B6: CCSS, rapport de mai 2026, tableau 1 (recettes 2025) ; valeur du point : calcul du simulateur | C6: https://www.securite-sociale.fr/files/live/sites/SSFR/files/medias/CCSS/2026/CCSS%20mai%202026_assembl%C3%A9_V2.pdf
A7: TVA : rendement et effet sur les prix | B7: DG Trésor, Trésor-Éco n° 371, septembre 2025, tableaux 1 et 2 | C7: https://www.tresor.economie.gouv.fr/Articles/2025/09/25/analyse-de-la-composition-des-recettes-de-tva
A8: Distribution des pensions | B8: Drees, échantillon interrégimes de retraités (EIR) 2020, tableau 5 | C8: https://data.drees.solidarites-sante.gouv.fr/explore/dataset/4178_distribution-des-pensions-mensuelles/information/
A9: Retraités | B9: Drees, effectifs de retraités fin 2024 (17,3 millions de retraités de droit direct, dont 16,4 en France) | C9: https://drees.solidarites-sante.gouv.fr/communique-de-presse-jeux-de-donnees/jeux-de-donnees/effectifs-de-retraites-et-montants-des
A10: Sous-indexation, taux d'annuité | B10: IPP, Perspectives budgétaires 2027, chapitre 3 : sous-indexation des retraites (Aubert, Tô, Tochev, 2026) | C10: https://www.ipp.eu/wp-content/uploads/2026/07/Chapitre_Desindexation_retraite___Rapport_Perspectives_Budgetaires_2027-4.pdf
A11: Décès | B11: Insee Première n° 2087, Bilan démographique 2025 | C11: https://www.insee.fr/fr/statistiques/8719824
A12: Épargne des ménages | B12: Insee Première n° 1815, 2020 (enquête Budget de famille 2017) | C12: https://www.insee.fr/fr/statistiques/4764600
A13: Niveaux de vie | B13: Insee, niveau de vie selon le statut d'activité (ERFS), euros constants 2024 | C13: https://www.insee.fr/fr/statistiques/2415628
A14: Composition des revenus | B14: COR, rapport annuel juin 2026, figure 3.8 : pensions 77,8 % du revenu des ménages retraités, revenus d'activité 84,1 % de celui des ménages actifs
A15: Rendement par génération | B15: COR, rapport annuel de juin 2026 | C15: https://www.cor-retraites.fr/sites/default/files/2026-06/RA_2026_def.pdf
A16: Impôts affectés aux retraites | B16: COR, « L'état du financement du système de retraite », séance du 17 octobre 2019 ; COR 2026, figure 2.11 | C16: https://www.cor-retraites.fr/sites/default/files/2019-11/Doc_2_%C3%A9tat_financement_0.pdf
A17: Emploi, salaires | B17: Insee, Emploi, chômage, revenus du travail, édition 2025 : 30,4 millions de personnes en emploi fin 2024 ; Insee, Comptes de la Nation 2024, tableau 6.205 (salaires et traitements bruts, total branches) | C17: https://www.insee.fr/fr/statistiques/8574681?sommaire=8574832
